Workbook

Sheet Overview
A1: Eligibility | B1: T10 customers with access to SIM / Range Skills.
B2: Agencies | C2: Points
A3: T10 - Full VR | B3: 653 | C3: 138085
A4: T10 - Skills Only | B4: 223 | C4: 6518
A5: T10 - Training Academy | B5: 4 | C5: 0 | D5: *No agency has an official APAP Footprint Size. In total there are 560 VR Customers with no Footprint Size, and another 145 with possible undercounted Footprint Sizes
A7: Total Eligible Cohort | B7: 880 | C7: 144603 | D7: *Does not considercurrent 6 month eligibility period
A10: Threshold | B10: Trailing 12 month SIM usage. | O10: 500 Ceiling | R10: 750 Ceiling | U10: 1000 Ceiling | Y10: T6 500 Ceiling
A11: Footprint Size | B11: Agencies | C11: Points | D11: APAP % | E11: % of Agencies | G11: w/ 500+ Ceiling | H11: Agencies | I11: Points | J11: APAP % | K11: % of Agencies | O11: Addtl. Agencies | P11: Addtl. Points | R11: Addtl. Agencies | S11: Addtl. Points | U11: Addtl. Agencies | V11: Addtl. Points | W11: APAP % | Y11: Addtl. Agencies | Z11: Addtl. Points | AA11: APAP %
A12: 2.0x SIM | B12: =COUNTIF('T10 Analysis'!$P$2:$P$881,">=2") -> 249 | C12: =SUMIF('T10 Analysis'!$P$2:$P$881,">=2",'T10 Analysis'!$G$2:$G$881) -> 25111 | D12: =C12/$C$7 -> 0.17365477 | E12: =B12/$B$7 -> 0.28295455 | G12: 2.0x SIM | H12: =B12+O12 -> 277 | I12: =C12+P12 -> 64904 | J12: =I12/$C$7 -> 0.44884269 | K12: =H12/$B$7 -> 0.31477273 | L12: =K12-E12 -> 0.031818182 | O12: =COUNTIFS('T10 Analysis'!$P$2:$P$881,"<2", 'T10 Analysis'!$S$2:$S$881, "TRUE") -> 28 | P12: =SUMIFS('T10 Analysis'!$G$2:$G$881,'T10 Analysis'!$P$2:$P$881,"<2", 'T10 Analysis'!$S$2:$S$881, "TRUE") -> 39793 | R12: =COUNTIFS('T10 Analysis'!$P$2:$P$881,"<2", 'T10 Analysis'!$T$2:$T$881, "TRUE") -> 15 | S12: =SUMIFS('T10 Analysis'!$G$2:$G$881,'T10 Analysis'!$P$2:$P$881,"<2", 'T10 Analysis'!$T$2:$T$881, "TRUE") -> 21979 | U12: =COUNTIFS('T10 Analysis'!$P$2:$P$881,"<2", 'T10 Analysis'!$U$2:$U$881, "TRUE") -> 11 | V12: =SUMIFS('T10 Analysis'!$G$2:$G$881,'T10 Analysis'!$P$2:$P$881,"<2", 'T10 Analysis'!$U$2:$U$881, "TRUE") -> 16081 | Y12: =COUNTIFS('T10 Analysis'!$P$2:$P$881,"<2", 'T10 Analysis'!$V$2:$V$881, "TRUE") -> 14 | Z12: =SUMIFS('T10 Analysis'!$G$2:$G$881,'T10 Analysis'!$P$2:$P$881,"<2", 'T10 Analysis'!$V$2:$V$881, "TRUE") -> 21485
A13: 1.5x SIM | B13: =COUNTIF('T10 Analysis'!$P$2:$P$881,">=1.5") -> 292 | C13: =SUMIF('T10 Analysis'!$P$2:$P$881,">=1.5",'T10 Analysis'!$G$2:$G$881) -> 31410 | D13: =C13/$C$7 -> 0.21721541 | E13: =B13/$B$7 -> 0.33181818 | G13: 1.5x SIM | H13: =B13+O13 -> 315 | I13: =C13+P13 -> 68109 | J13: =I13/$C$7 -> 0.47100683 | K13: =H13/$B$7 -> 0.35795455 | L13: =K13-E13 -> 0.026136364 | O13: =COUNTIFS('T10 Analysis'!$P$2:$P$881,"<1.5", 'T10 Analysis'!$S$2:$S$881, "TRUE") -> 23 | P13: =SUMIFS('T10 Analysis'!$G$2:$G$881,'T10 Analysis'!$P$2:$P$881,"<1.5", 'T10 Analysis'!$S$2:$S$881, "TRUE") -> 36699 | R13: =COUNTIFS('T10 Analysis'!$P$2:$P$881,"<1.5", 'T10 Analysis'!$T$2:$T$881, "TRUE") -> 12 | S13: =SUMIFS('T10 Analysis'!$G$2:$G$881,'T10 Analysis'!$P$2:$P$881,"<1.5", 'T10 Analysis'!$T$2:$T$881, "TRUE") -> 19525 | U13: =COUNTIFS('T10 Analysis'!$P$2:$P$881,"<1.5", 'T10 Analysis'!$U$2:$U$881, "TRUE") -> 10 | V13: =SUMIFS('T10 Analysis'!$G$2:$G$881,'T10 Analysis'!$P$2:$P$881,"<1.5", 'T10 Analysis'!$U$2:$U$881, "TRUE") -> 14623 | W13: =(V13+C13)/$C$7 -> 0.31834056 | Y13: =COUNTIFS('T10 Analysis'!$P$2:$P$881,"<1.5", 'T10 Analysis'!$V$2:$V$881, "TRUE") -> 12 | Z13: =SUMIFS('T10 Analysis'!$G$2:$G$881,'T10 Analysis'!$P$2:$P$881,"<1.5", 'T10 Analysis'!$V$2:$V$881, "TRUE") -> 19683 | AA13: =(Z13+C13)/$C$7 -> 0.35333292
A14: 1.0x SIM | B14: =COUNTIF('T10 Analysis'!$P$2:$P$881,">=1") -> 348 | C14: =SUMIF('T10 Analysis'!$P$2:$P$881,">=1",'T10 Analysis'!$G$2:$G$881) -> 46397 | D14: =C14/$C$7 -> 0.3208578 | E14: =B14/$B$7 -> 0.39545455 | G14: 1.0x SIM | H14: =B14+O14 -> 361 | I14: =C14+P14 -> 70853 | J14: =I14/$C$7 -> 0.48998292 | K14: =H14/$B$7 -> 0.41022727 | L14: =K14-E14 -> 0.014772727 | O14: =COUNTIFS('T10 Analysis'!$P$2:$P$881,"<1", 'T10 Analysis'!$S$2:$S$881, "TRUE") -> 13 | P14: =SUMIFS('T10 Analysis'!$G$2:$G$881,'T10 Analysis'!$P$2:$P$881,"<1", 'T10 Analysis'!$S$2:$S$881, "TRUE") -> 24456 | R14: =COUNTIFS('T10 Analysis'!$P$2:$P$881,"<1", 'T10 Analysis'!$T$2:$T$881, "TRUE") -> 4 | S14: =SUMIFS('T10 Analysis'!$G$2:$G$881,'T10 Analysis'!$P$2:$P$881,"<1", 'T10 Analysis'!$T$2:$T$881, "TRUE") -> 8472 | U14: =COUNTIFS('T10 Analysis'!$P$2:$P$881,"<1", 'T10 Analysis'!$U$2:$U$881, "TRUE") -> 3 | V14: =SUMIFS('T10 Analysis'!$G$2:$G$881,'T10 Analysis'!$P$2:$P$881,"<1", 'T10 Analysis'!$U$2:$U$881, "TRUE") -> 4288 | Y14: =COUNTIFS('T10 Analysis'!$P$2:$P$881,"<1", 'T10 Analysis'!$V$2:$V$881, "TRUE") -> 5 | Z14: =SUMIFS('T10 Analysis'!$G$2:$G$881,'T10 Analysis'!$P$2:$P$881,"<1", 'T10 Analysis'!$V$2:$V$881, "TRUE") -> 10045
A15: 0.5x SIM | B15: =COUNTIF('T10 Analysis'!$P$2:$P$881,">=0.5") -> 420 | C15: =SUMIF('T10 Analysis'!$P$2:$P$881,">=0.5",'T10 Analysis'!$G$2:$G$881) -> 59419 | D15: =C15/$C$7 -> 0.41091125 | E15: =B15/$B$7 -> 0.47727273 | G15: 0.5x SIM | H15: =B15+O15 -> 429 | I15: =C15+P15 -> 77771 | J15: =I15/$C$7 -> 0.53782425 | K15: =H15/$B$7 -> 0.4875 | L15: =K15-E15 -> 0.010227273 | O15: =COUNTIFS('T10 Analysis'!$P$2:$P$881,"<0.5", 'T10 Analysis'!$S$2:$S$881, "TRUE") -> 9 | P15: =SUMIFS('T10 Analysis'!$G$2:$G$881,'T10 Analysis'!$P$2:$P$881,"<0.5", 'T10 Analysis'!$S$2:$S$881, "TRUE") -> 18352 | R15: =COUNTIFS('T10 Analysis'!$P$2:$P$881,"<0.5", 'T10 Analysis'!$T$2:$T$881, "TRUE") -> 2 | S15: =SUMIFS('T10 Analysis'!$G$2:$G$881,'T10 Analysis'!$P$2:$P$881,"<0.5", 'T10 Analysis'!$T$2:$T$881, "TRUE") -> 4184 | U15: =COUNTIFS('T10 Analysis'!$P$2:$P$881,"<0.5", 'T10 Analysis'!$U$2:$U$881, "TRUE") -> 1 | V15: =SUMIFS('T10 Analysis'!$G$2:$G$881,'T10 Analysis'!$P$2:$P$881,"<0.5", 'T10 Analysis'!$U$2:$U$881, "TRUE") -> 0 | Y15: =COUNTIFS('T10 Analysis'!$P$2:$P$881,"<0.5", 'T10 Analysis'!$V$2:$V$881, "TRUE") -> 4 | Z15: =SUMIFS('T10 Analysis'!$G$2:$G$881,'T10 Analysis'!$P$2:$P$881,"<0.5", 'T10 Analysis'!$V$2:$V$881, "TRUE") -> 7845
A18: VR License Counts | B18: Agencies | C18: Points | D18: APAP % | E18: % of Agencies | G18: w/ 500+ Ceiling | H18: Agencies | I18: Points | J18: APAP % | K18: % of Agencies | O18: Addtl. Agencies | P18: Addtl. Points | R18: Addtl. Agencies | S18: Addtl. Points | U18: Addtl. Agencies | V18: Addtl. Points | W18: APAP % | Y18: Addtl. Agencies | Z18: Addtl. Points
A19: 2.0x SIM | B19: =COUNTIF('T10 Analysis'!$Q$2:$Q$881,">=2") -> 227 | C19: =SUMIF('T10 Analysis'!$Q$2:$Q$881,">=2",'T10 Analysis'!$G$2:$G$881) -> 28716 | D19: =C19/$C$7 -> 0.19858509 | E19: =B19/$B$7 -> 0.25795455 | G19: 2.0x SIM | H19: =B19+O19 -> 262 | I19: =C19+P19 -> 67370 | J19: =I19/$C$7 -> 0.46589628 | K19: =H19/$B$7 -> 0.29772727 | L19: =K19-E19 -> 0.039772727 | O19: =COUNTIFS('T10 Analysis'!$Q$2:$Q$881,"<2", 'T10 Analysis'!$S$2:$S$881, "TRUE") -> 35 | P19: =SUMIFS('T10 Analysis'!$G$2:$G$881,'T10 Analysis'!$Q$2:$Q$881,"<2", 'T10 Analysis'!$S$2:$S$881, "TRUE") -> 38654 | R19: =COUNTIFS('T10 Analysis'!$Q$2:$Q$881,"<2", 'T10 Analysis'!$T$2:$T$881, "TRUE") -> 21 | S19: =SUMIFS('T10 Analysis'!$G$2:$G$881,'T10 Analysis'!$Q$2:$Q$881,"<2", 'T10 Analysis'!$T$2:$T$881, "TRUE") -> 20815 | U19: =COUNTIFS('T10 Analysis'!$Q$2:$Q$881,"<2", 'T10 Analysis'!$U$2:$U$881, "TRUE") -> 16 | V19: =SUMIFS('T10 Analysis'!$G$2:$G$881,'T10 Analysis'!$Q$2:$Q$881,"<2", 'T10 Analysis'!$U$2:$U$881, "TRUE") -> 14540 | Y19: =COUNTIFS('T10 Analysis'!$Q$2:$Q$881,"<2", 'T10 Analysis'!$V$2:$V$881, "TRUE") -> 19 | Z19: =SUMIFS('T10 Analysis'!$G$2:$G$881,'T10 Analysis'!$Q$2:$Q$881,"<2", 'T10 Analysis'!$V$2:$V$881, "TRUE") -> 19978
A20: 1.5x SIM | B20: =COUNTIF('T10 Analysis'!$Q$2:$Q$881,">=1.5") -> 277 | C20: =SUMIF('T10 Analysis'!$Q$2:$Q$881,">=1.5",'T10 Analysis'!$G$2:$G$881) -> 36046 | D20: =C20/$C$7 -> 0.2492756 | E20: =B20/$B$7 -> 0.31477273 | G20: 1.5x SIM | H20: =B20+O20 -> 302 | I20: =C20+P20 -> 70126 | J20: =I20/$C$7 -> 0.48495536 | K20: =H20/$B$7 -> 0.34318182 | L20: =K20-E20 -> 0.028409091 | O20: =COUNTIFS('T10 Analysis'!$Q$2:$Q$881,"<1.5", 'T10 Analysis'!$S$2:$S$881, "TRUE") -> 25 | P20: =SUMIFS('T10 Analysis'!$G$2:$G$881,'T10 Analysis'!$Q$2:$Q$881,"<1.5", 'T10 Analysis'!$S$2:$S$881, "TRUE") -> 34080 | R20: =COUNTIFS('T10 Analysis'!$Q$2:$Q$881,"<1.5", 'T10 Analysis'!$T$2:$T$881, "TRUE") -> 14 | S20: =SUMIFS('T10 Analysis'!$G$2:$G$881,'T10 Analysis'!$Q$2:$Q$881,"<1.5", 'T10 Analysis'!$T$2:$T$881, "TRUE") -> 17202 | U20: =COUNTIFS('T10 Analysis'!$Q$2:$Q$881,"<1.5", 'T10 Analysis'!$U$2:$U$881, "TRUE") -> 12 | V20: =SUMIFS('T10 Analysis'!$G$2:$G$881,'T10 Analysis'!$Q$2:$Q$881,"<1.5", 'T10 Analysis'!$U$2:$U$881, "TRUE") -> 12300 | W20: =(V20+C20)/$C$7 -> 0.33433608 | Y20: =COUNTIFS('T10 Analysis'!$Q$2:$Q$881,"<1.5", 'T10 Analysis'!$V$2:$V$881, "TRUE") -> 13 | Z20: =SUMIFS('T10 Analysis'!$G$2:$G$881,'T10 Analysis'!$Q$2:$Q$881,"<1.5", 'T10 Analysis'!$V$2:$V$881, "TRUE") -> 17264 | AA20: =(Z20+C20)/$C$7 -> 0.36866455
A21: 1.0x SIM | B21: =COUNTIF('T10 Analysis'!$Q$2:$Q$881,">=1") -> 355 | C21: =SUMIF('T10 Analysis'!$Q$2:$Q$881,">=1",'T10 Analysis'!$G$2:$G$881) -> 48389 | D21: =C21/$C$7 -> 0.33463344 | E21: =B21/$B$7 -> 0.40340909 | G21: 1.0x SIM | H21: =B21+O21 -> 372 | I21: =C21+P21 -> 74321 | J21: =I21/$C$7 -> 0.51396582 | K21: =H21/$B$7 -> 0.42272727 | L21: =K21-E21 -> 0.019318182 | O21: =COUNTIFS('T10 Analysis'!$Q$2:$Q$881,"<1", 'T10 Analysis'!$S$2:$S$881, "TRUE") -> 17 | P21: =SUMIFS('T10 Analysis'!$G$2:$G$881,'T10 Analysis'!$Q$2:$Q$881,"<1", 'T10 Analysis'!$S$2:$S$881, "TRUE") -> 25932 | R21: =COUNTIFS('T10 Analysis'!$Q$2:$Q$881,"<1", 'T10 Analysis'!$T$2:$T$881, "TRUE") -> 8 | S21: =SUMIFS('T10 Analysis'!$G$2:$G$881,'T10 Analysis'!$Q$2:$Q$881,"<1", 'T10 Analysis'!$T$2:$T$881, "TRUE") -> 9757 | U21: =COUNTIFS('T10 Analysis'!$Q$2:$Q$881,"<1", 'T10 Analysis'!$U$2:$U$881, "TRUE") -> 6 | V21: =SUMIFS('T10 Analysis'!$G$2:$G$881,'T10 Analysis'!$Q$2:$Q$881,"<1", 'T10 Analysis'!$U$2:$U$881, "TRUE") -> 4855 | Y21: =COUNTIFS('T10 Analysis'!$Q$2:$Q$881,"<1", 'T10 Analysis'!$V$2:$V$881, "TRUE") -> 7 | Z21: =SUMIFS('T10 Analysis'!$G$2:$G$881,'T10 Analysis'!$Q$2:$Q$881,"<1", 'T10 Analysis'!$V$2:$V$881, "TRUE") -> 10516
A22: 0.5x SIM | B22: =COUNTIF('T10 Analysis'!$Q$2:$Q$881,">=0.5") -> 448 | C22: =SUMIF('T10 Analysis'!$Q$2:$Q$881,">=0.5",'T10 Analysis'!$G$2:$G$881) -> 61783 | D22: =C22/$C$7 -> 0.42725946 | E22: =B22/$B$7 -> 0.50909091 | G22: 0.5x SIM | H22: =B22+O22 -> 456 | I22: =C22+P22 -> 80788 | J22: =I22/$C$7 -> 0.55868827 | K22: =H22/$B$7 -> 0.51818182 | L22: =K22-E22 -> 0.0090909091 | O22: =COUNTIFS('T10 Analysis'!$Q$2:$Q$881,"<0.5", 'T10 Analysis'!$S$2:$S$881, "TRUE") -> 8 | P22: =SUMIFS('T10 Analysis'!$G$2:$G$881,'T10 Analysis'!$Q$2:$Q$881,"<0.5", 'T10 Analysis'!$S$2:$S$881, "TRUE") -> 19005 | R22: =COUNTIFS('T10 Analysis'!$Q$2:$Q$881,"<0.5", 'T10 Analysis'!$T$2:$T$881, "TRUE") -> 3 | S22: =SUMIFS('T10 Analysis'!$G$2:$G$881,'T10 Analysis'!$Q$2:$Q$881,"<0.5", 'T10 Analysis'!$T$2:$T$881, "TRUE") -> 6368 | U22: =COUNTIFS('T10 Analysis'!$Q$2:$Q$881,"<0.5", 'T10 Analysis'!$U$2:$U$881, "TRUE") -> 2 | V22: =SUMIFS('T10 Analysis'!$G$2:$G$881,'T10 Analysis'!$Q$2:$Q$881,"<0.5", 'T10 Analysis'!$U$2:$U$881, "TRUE") -> 2184 | Y22: =COUNTIFS('T10 Analysis'!$Q$2:$Q$881,"<0.5", 'T10 Analysis'!$V$2:$V$881, "TRUE") -> 2 | Z22: =SUMIFS('T10 Analysis'!$G$2:$G$881,'T10 Analysis'!$Q$2:$Q$881,"<0.5", 'T10 Analysis'!$V$2:$V$881, "TRUE") -> 6766
A25: CEW Counts | B25: Agencies | C25: Points | D25: APAP % | E25: % of Agencies | G25: w/ 500+ Ceiling | H25: Agencies | I25: Points | J25: APAP % | K25: % of Agencies | O25: Addtl. Agencies | P25: Addtl. Points | R25: Addtl. Agencies | S25: Addtl. Points | U25: Addtl. Agencies | V25: Addtl. Points | W25: APAP % | Y25: Addtl. Agencies | Z25: Addtl. Points | AA25: APAP %
A26: 2.0x SIM | B26: =COUNTIF('T10 Analysis'!$R$2:$R$881,">=2") -> 253 | C26: =SUMIF('T10 Analysis'!$R$2:$R$881,">=2",'T10 Analysis'!$G$2:$G$881) -> 29902 | D26: =C26/$C$7 -> 0.20678686 | E26: =B26/$B$7 -> 0.2875 | G26: 2.0x SIM | H26: =B26+O26 -> 281 | I26: =C26+P26 -> 67195 | J26: =I26/$C$7 -> 0.46468607 | K26: =H26/$B$7 -> 0.31931818 | L26: =K26-E26 -> 0.031818182 | O26: =COUNTIFS('T10 Analysis'!$R$2:$R$881,"<2", 'T10 Analysis'!$S$2:$S$881, "TRUE") -> 28 | P26: =SUMIFS('T10 Analysis'!$G$2:$G$881,'T10 Analysis'!$R$2:$R$881,"<2", 'T10 Analysis'!$S$2:$S$881, "TRUE") -> 37293 | R26: =COUNTIFS('T10 Analysis'!$R$2:$R$881,"<2", 'T10 Analysis'!$T$2:$T$881, "TRUE") -> 17 | S26: =SUMIFS('T10 Analysis'!$G$2:$G$881,'T10 Analysis'!$R$2:$R$881,"<2", 'T10 Analysis'!$T$2:$T$881, "TRUE") -> 20478 | U26: =COUNTIFS('T10 Analysis'!$R$2:$R$881,"<2", 'T10 Analysis'!$U$2:$U$881, "TRUE") -> 12 | V26: =SUMIFS('T10 Analysis'!$G$2:$G$881,'T10 Analysis'!$R$2:$R$881,"<2", 'T10 Analysis'!$U$2:$U$881, "TRUE") -> 14203 | Y26: =COUNTIFS('T10 Analysis'!$P$2:$P$881,"<2", 'T10 Analysis'!$V$2:$V$881, "TRUE") -> 14 | Z26: =SUMIFS('T10 Analysis'!$G$2:$G$881,'T10 Analysis'!$Q$2:$Q$881,"<2", 'T10 Analysis'!$V$2:$V$881, "TRUE") -> 19978
A27: 1.5x SIM | B27: =COUNTIF('T10 Analysis'!$R$2:$R$881,">=1.5") -> 292 | C27: =SUMIF('T10 Analysis'!$R$2:$R$881,">=1.5",'T10 Analysis'!$G$2:$G$881) -> 35890 | D27: =C27/$C$7 -> 0.24819679 | E27: =B27/$B$7 -> 0.33181818 | G27: 1.5x SIM | H27: =B27+O27 -> 313 | I27: =C27+P27 -> 68844 | J27: =I27/$C$7 -> 0.47608971 | K27: =H27/$B$7 -> 0.35568182 | L27: =K27-E27 -> 0.023863636 | O27: =COUNTIFS('T10 Analysis'!$R$2:$R$881,"<1.5", 'T10 Analysis'!$S$2:$S$881, "TRUE") -> 21 | P27: =SUMIFS('T10 Analysis'!$G$2:$G$881,'T10 Analysis'!$R$2:$R$881,"<1.5", 'T10 Analysis'!$S$2:$S$881, "TRUE") -> 32954 | R27: =COUNTIFS('T10 Analysis'!$R$2:$R$881,"<1.5", 'T10 Analysis'!$T$2:$T$881, "TRUE") -> 12 | S27: =SUMIFS('T10 Analysis'!$G$2:$G$881,'T10 Analysis'!$R$2:$R$881,"<1.5", 'T10 Analysis'!$T$2:$T$881, "TRUE") -> 16970 | U27: =COUNTIFS('T10 Analysis'!$R$2:$R$881,"<1.5", 'T10 Analysis'!$U$2:$U$881, "TRUE") -> 10 | V27: =SUMIFS('T10 Analysis'!$G$2:$G$881,'T10 Analysis'!$R$2:$R$881,"<1.5", 'T10 Analysis'!$U$2:$U$881, "TRUE") -> 12068 | W27: =(V27+C27)/$C$7 -> 0.33165287 | Y27: =COUNTIFS('T10 Analysis'!$P$2:$P$881,"<1.5", 'T10 Analysis'!$V$2:$V$881, "TRUE") -> 12 | Z27: =SUMIFS('T10 Analysis'!$G$2:$G$881,'T10 Analysis'!$Q$2:$Q$881,"<1.5", 'T10 Analysis'!$V$2:$V$881, "TRUE") -> 17264 | AA27: =(Z27+C27)/$C$7 -> 0.36758573
A28: 1.0x SIM | B28: =COUNTIF('T10 Analysis'!$R$2:$R$881,">=1") -> 372 | C28: =SUMIF('T10 Analysis'!$R$2:$R$881,">=1",'T10 Analysis'!$G$2:$G$881) -> 51047 | D28: =C28/$C$7 -> 0.35301481 | E28: =B28/$B$7 -> 0.42272727 | G28: 1.0x SIM | H28: =B28+O28 -> 385 | I28: =C28+P28 -> 73959 | J28: =I28/$C$7 -> 0.51146242 | K28: =H28/$B$7 -> 0.4375 | L28: =K28-E28 -> 0.014772727 | O28: =COUNTIFS('T10 Analysis'!$R$2:$R$881,"<1", 'T10 Analysis'!$S$2:$S$881, "TRUE") -> 13 | P28: =SUMIFS('T10 Analysis'!$G$2:$G$881,'T10 Analysis'!$R$2:$R$881,"<1", 'T10 Analysis'!$S$2:$S$881, "TRUE") -> 22912 | R28: =COUNTIFS('T10 Analysis'!$R$2:$R$881,"<1", 'T10 Analysis'!$T$2:$T$881, "TRUE") -> 5 | S28: =SUMIFS('T10 Analysis'!$G$2:$G$881,'T10 Analysis'!$R$2:$R$881,"<1", 'T10 Analysis'!$T$2:$T$881, "TRUE") -> 7816 | U28: =COUNTIFS('T10 Analysis'!$R$2:$R$881,"<1", 'T10 Analysis'!$U$2:$U$881, "TRUE") -> 4 | V28: =SUMIFS('T10 Analysis'!$G$2:$G$881,'T10 Analysis'!$R$2:$R$881,"<1", 'T10 Analysis'!$U$2:$U$881, "TRUE") -> 3632 | Y28: =COUNTIFS('T10 Analysis'!$P$2:$P$881,"<1", 'T10 Analysis'!$V$2:$V$881, "TRUE") -> 5 | Z28: =SUMIFS('T10 Analysis'!$G$2:$G$881,'T10 Analysis'!$Q$2:$Q$881,"<1", 'T10 Analysis'!$V$2:$V$881, "TRUE") -> 10516
A29: 0.5x SIM | B29: =COUNTIF('T10 Analysis'!$R$2:$R$881,">=0.5") -> 468 | C29: =SUMIF('T10 Analysis'!$R$2:$R$881,">=0.5",'T10 Analysis'!$G$2:$G$881) -> 67617 | D29: =C29/$C$7 -> 0.46760441 | E29: =B29/$B$7 -> 0.53181818 | G29: 0.5x SIM | H29: =B29+O29 -> 472 | I29: =C29+P29 -> 81899 | J29: =I29/$C$7 -> 0.56637138 | K29: =H29/$B$7 -> 0.53636364 | L29: =K29-E29 -> 0.0045454545 | O29: =COUNTIFS('T10 Analysis'!$R$2:$R$881,"<0.5", 'T10 Analysis'!$S$2:$S$881, "TRUE") -> 4 | P29: =SUMIFS('T10 Analysis'!$G$2:$G$881,'T10 Analysis'!$R$2:$R$881,"<0.5", 'T10 Analysis'!$S$2:$S$881, "TRUE") -> 14282 | R29: =COUNTIFS('T10 Analysis'!$R$2:$R$881,"<0.5", 'T10 Analysis'!$T$2:$T$881, "TRUE") -> 1 | S29: =SUMIFS('T10 Analysis'!$G$2:$G$881,'T10 Analysis'!$R$2:$R$881,"<0.5", 'T10 Analysis'!$T$2:$T$881, "TRUE") -> 4184 | U29: =COUNTIFS('T10 Analysis'!$R$2:$R$881,"<0.5", 'T10 Analysis'!$U$2:$U$881, "TRUE") -> 0 | V29: =SUMIFS('T10 Analysis'!$G$2:$G$881,'T10 Analysis'!$R$2:$R$881,"<0.5", 'T10 Analysis'!$U$2:$U$881, "TRUE") -> 0 | Y29: =COUNTIFS('T10 Analysis'!$P$2:$P$881,"<0.5", 'T10 Analysis'!$V$2:$V$881, "TRUE") -> 4 | Z29: =SUMIFS('T10 Analysis'!$G$2:$G$881,'T10 Analysis'!$Q$2:$Q$881,"<0.5", 'T10 Analysis'!$V$2:$V$881, "TRUE") -> 6766
A32: Threhold Ceiling | B32: Agencies | C32: Points | D32: APAP % | E32: % of Agencies
A33: 1000+ Trainings | B33: =COUNTIF('T10 Analysis'!U2:U881,TRUE) -> 42 | C33: =SUMIF('T10 Analysis'!$U$2:$U$881,"TRUE",'T10 Analysis'!$G$2:$G$881) -> 30499 | D33: =C33/$C$7 -> 0.2109154 | E33: =B33/$B$7 -> 0.047727273
A34: 750+ Trainings | B34: =COUNTIF('T10 Analysis'!T2:T881,TRUE) -> 55 | C34: =SUMIF('T10 Analysis'!$T$2:$T$881,"TRUE",'T10 Analysis'!$G$2:$G$881) -> 38671 | D34: =C34/$C$7 -> 0.26742875 | E34: =B34/$B$7 -> 0.0625
A35: 500+ Trainings | B35: =COUNTIF('T10 Analysis'!S2:S881,TRUE) -> 91 | C35: =SUMIF('T10 Analysis'!$S$2:$S$881,"TRUE",'T10 Analysis'!$G$2:$G$881) -> 59751 | D35: =C35/$C$7 -> 0.41320719 | E35: =B35/$B$7 -> 0.10340909

Sheet T10 Analysis
A1: Account Number | B1: Account Name | C1: T12 SIM Usage | D1: T6 SIM Completions | E1: Number of Officers | F1: Active License Quantity | G1: Footprint Size | H1: Total T10 CEWs | I1: TASER Type | J1: Active License Type | K1: VR HW Purchase Date | L1: First PSO Start Date | M1: Account Line Size | N1: Time as Customer | O1: Footprint Difference | P1: Threshold - Footprint | Q1: Threshold - License | R1: Threshold - CEW | S1: 500+ Events | T1: 750+ Events | U1: 1000+ Events | V1: T6 500+ Events
A2: 100003 | B2: Oregon Health and Science University Police Dept. | C2: 78 | D2: 0 | E2: 25 | F2: 40 | G2: 0 | H2: 41 | I2: T10 | J2: Full VR | K2: 45202 | M2: Inside | N2: 25 | O2: 0 | P2: 0 | Q2: =C2/F2 -> 1.95 | R2: =C2/H2 -> 1.902439 | S2: =IF(C2>500,TRUE,FALSE) -> FALSE | T2: =IF(C2>750,TRUE,FALSE) -> FALSE | U2: =IF(C2>1000,TRUE,FALSE) -> FALSE | V2: =IF(D2>500,TRUE,FALSE) -> FALSE
A3: 100239 | B3: Culver City Police Department - CA | C3: 133 | D3: 0 | E3: 113 | F3: 100 | G3: 100 | H3: 31 | I3: T10 | J3: Full VR | K3: 45565 | L3: 45644 | M3: T1200 | N3: 11 | O3: 1 | P3: =C3/G3 -> 1.33 | Q3: =C3/F3 -> 1.33 | R3: =C3/H3 -> 4.2903226 | S3: =IF(C3>500,TRUE,FALSE) -> FALSE | T3: =IF(C3>750,TRUE,FALSE) -> FALSE | U3: =IF(C3>1000,TRUE,FALSE) -> FALSE | V3: =IF(D3>500,TRUE,FALSE) -> FALSE
A4: 105331 | B4: Glendale Police Dept. - AZ | C4: 6 | D4: 6 | E4: 439 | F4: 487 | G4: 480 | H4: 471 | I4: T10 | J4: Full VR | K4: 45581 | L4: 45796 | M4: T1200 | N4: 40 | O4: 0.98562628 | P4: =C4/G4 -> 0.0125 | Q4: =C4/F4 -> 0.012320329 | R4: =C4/H4 -> 0.012738854 | S4: =IF(C4>500,TRUE,FALSE) -> FALSE | T4: =IF(C4>750,TRUE,FALSE) -> FALSE | U4: =IF(C4>1000,TRUE,FALSE) -> FALSE | V4: =IF(D4>500,TRUE,FALSE) -> FALSE
A5: 105389 | B5: Bensalem Township Police Dept. - PA | C5: 17 | D5: 8 | E5: 102 | F5: 184 | G5: 111 | H5: 95 | I5: T10 | J5: Full VR | K5: 45894 | M5: T1200 | N5: 48 | O5: 0.60326087 | P5: =C5/G5 -> 0.15315315 | Q5: =C5/F5 -> 0.092391304 | R5: =C5/H5 -> 0.17894737 | S5: =IF(C5>500,TRUE,FALSE) -> FALSE | T5: =IF(C5>750,TRUE,FALSE) -> FALSE | U5: =IF(C5>1000,TRUE,FALSE) -> FALSE | V5: =IF(D5>500,TRUE,FALSE) -> FALSE
A6: 105469 | B6: San Bernardino County Sheriff's Dept. - CA | C6: 4462 | D6: 1025 | E6: 2385 | F6: 1000 | G6: 950 | H6: 2066 | I6: T10 | J6: Full VR | K6: 45596 | L6: 45713 | M6: Major | N6: 10 | O6: 0.95 | P6: =C6/G6 -> 4.6968421 | Q6: =C6/F6 -> 4.462 | R6: =C6/H6 -> 2.1597289 | S6: =IF(C6>500,TRUE,FALSE) -> TRUE | T6: =IF(C6>750,TRUE,FALSE) -> TRUE | U6: =IF(C6>1000,TRUE,FALSE) -> TRUE | V6: =IF(D6>500,TRUE,FALSE) -> TRUE
A7: 105506 | B7: Chandler Police Dept. - AZ | C7: 413 | D7: 100 | E7: 328 | F7: 364 | G7: 394 | H7: 376 | I7: T10 | J7: Full VR | K7: 45502 | M7: T1200 | N7: 13 | O7: 1.0824176 | P7: =C7/G7 -> 1.0482234 | Q7: =C7/F7 -> 1.1346154 | R7: =C7/H7 -> 1.0984043 | S7: =IF(C7>500,TRUE,FALSE) -> FALSE | T7: =IF(C7>750,TRUE,FALSE) -> FALSE | U7: =IF(C7>1000,TRUE,FALSE) -> FALSE | V7: =IF(D7>500,TRUE,FALSE) -> FALSE
A8: 105516 | B8: Mesa Police Department | C8: 508 | D8: 521 | E8: 854 | F8: 720 | G8: 1079 | H8: 930 | I8: T10 | J8: Full VR | K8: 45468 | M8: Major | N8: 16 | O8: 1.4986111 | P8: =C8/G8 -> 0.4708063 | Q8: =C8/F8 -> 0.70555556 | R8: =C8/H8 -> 0.54623656 | S8: =IF(C8>500,TRUE,FALSE) -> TRUE | T8: =IF(C8>750,TRUE,FALSE) -> FALSE | U8: =IF(C8>1000,TRUE,FALSE) -> FALSE | V8: =IF(D8>500,TRUE,FALSE) -> TRUE
A9: 105678 | B9: East Point Police Dept. - GA | C9: 64 | D9: 17 | E9: 120 | F9: 115 | G9: 90 | H9: 118 | I9: T10 | J9: Full VR | K9: 45849 | L9: 46035 | M9: T1200 | N9: 42 | O9: 0.7826087 | P9: =C9/G9 -> 0.71111111 | Q9: =C9/F9 -> 0.55652174 | R9: =C9/H9 -> 0.54237288 | S9: =IF(C9>500,TRUE,FALSE) -> FALSE | T9: =IF(C9>750,TRUE,FALSE) -> FALSE | U9: =IF(C9>1000,TRUE,FALSE) -> FALSE | V9: =IF(D9>500,TRUE,FALSE) -> FALSE
A10: 105702 | B10: Tampa Police Department - FL | C10: 719 | D10: 474 | E10: 924 | F10: 1350 | G10: 928 | H10: 762 | I10: T10 | J10: Full VR | K10: 45653 | L10: 45748 | M10: Major | N10: 11 | O10: 0.68740741 | P10: =C10/G10 -> 0.77478448 | Q10: =C10/F10 -> 0.53259259 | R10: =C10/H10 -> 0.94356955 | S10: =IF(C10>500,TRUE,FALSE) -> TRUE | T10: =IF(C10>750,TRUE,FALSE) -> FALSE | U10: =IF(C10>1000,TRUE,FALSE) -> FALSE | V10: =IF(D10>500,TRUE,FALSE) -> FALSE
A11: 105721 | B11: San Mateo Police Dept. - CA | C11: 11 | D11: 6 | E11: 115 | F11: 132 | G11: 142 | H11: 136 | I11: T10 | J11: Full VR | K11: 45642 | M11: T1200 | N11: 36 | O11: 1.0757576 | P11: =C11/G11 -> 0.077464789 | Q11: =C11/F11 -> 0.083333333 | R11: =C11/H11 -> 0.080882353 | S11: =IF(C11>500,TRUE,FALSE) -> FALSE | T11: =IF(C11>750,TRUE,FALSE) -> FALSE | U11: =IF(C11>1000,TRUE,FALSE) -> FALSE | V11: =IF(D11>500,TRUE,FALSE) -> FALSE
A12: 105754 | B12: Corona Police Dept. - CA | C12: 4 | D12: 0 | E12: 159 | F12: 166 | G12: 228 | H12: 171 | I12: T10 | J12: Full VR | K12: 45239 | M12: T1200 | N12: 21 | O12: 1.373494 | P12: =C12/G12 -> 0.01754386 | Q12: =C12/F12 -> 0.024096386 | R12: =C12/H12 -> 0.023391813 | S12: =IF(C12>500,TRUE,FALSE) -> FALSE | T12: =IF(C12>750,TRUE,FALSE) -> FALSE | U12: =IF(C12>1000,TRUE,FALSE) -> FALSE | V12: =IF(D12>500,TRUE,FALSE) -> FALSE
A13: 105756 | B13: Pueblo Police Department - CO | C13: 111 | D13: 60 | E13: 222 | F13: 271 | G13: 195 | H13: 245 | I13: T10 | J13: Full VR | K13: 45631 | L13: 45757 | M13: T1200 | N13: 9 | O13: 0.7195572 | P13: =C13/G13 -> 0.56923077 | Q13: =C13/F13 -> 0.4095941 | R13: =C13/H13 -> 0.45306122 | S13: =IF(C13>500,TRUE,FALSE) -> FALSE | T13: =IF(C13>750,TRUE,FALSE) -> FALSE | U13: =IF(C13>1000,TRUE,FALSE) -> FALSE | V13: =IF(D13>500,TRUE,FALSE) -> FALSE
A14: 105779 | B14: Amarillo Police Dept - TX | C14: 147 | D14: 13 | E14: 354 | F14: 268 | G14: 446 | H14: 258 | I14: T10 | J14: Full VR | K14: 45314 | L14: 45671 | M14: T1200 | N14: 18 | O14: 1.6641791 | P14: =C14/G14 -> 0.32959641 | Q14: =C14/F14 -> 0.54850746 | R14: =C14/H14 -> 0.56976744 | S14: =IF(C14>500,TRUE,FALSE) -> FALSE | T14: =IF(C14>750,TRUE,FALSE) -> FALSE | U14: =IF(C14>1000,TRUE,FALSE) -> FALSE | V14: =IF(D14>500,TRUE,FALSE) -> FALSE
A15: 105780 | B15: Homestead Police Dept.- FL | C15: 377 | D15: 427 | E15: 135 | F15: 241 | G15: 120 | H15: 62 | I15: T10 | J15: Full VR | K15: 45653 | L15: 45939 | M15: T1200 | N15: 7 | O15: 0.49792531 | P15: =C15/G15 -> 3.1416667 | Q15: =C15/F15 -> 1.5643154 | R15: =C15/H15 -> 6.0806452 | S15: =IF(C15>500,TRUE,FALSE) -> FALSE | T15: =IF(C15>750,TRUE,FALSE) -> FALSE | U15: =IF(C15>1000,TRUE,FALSE) -> FALSE | V15: =IF(D15>500,TRUE,FALSE) -> FALSE
A16: 105785 | B16: Fort Worth Police Department - TX | C16: 2323 | D16: 2003 | E16: 1717 | F16: 3861 | G16: 1993 | H16: 1904 | I16: T10 | J16: Full VR | K16: 45048 | M16: Major | N16: 45 | O16: 0.51618752 | P16: =C16/G16 -> 1.1655795 | Q16: =C16/F16 -> 0.6016576 | R16: =C16/H16 -> 1.220063 | S16: =IF(C16>500,TRUE,FALSE) -> TRUE | T16: =IF(C16>750,TRUE,FALSE) -> TRUE | U16: =IF(C16>1000,TRUE,FALSE) -> TRUE | V16: =IF(D16>500,TRUE,FALSE) -> TRUE
A17: 105857 | B17: Santa Ana Police Dept - CA | C17: 0 | D17: 0 | E17: 335 | F17: 369 | G17: 419 | H17: 413 | I17: T10 | J17: Full VR | K17: 45589 | M17: T1200 | N17: 40 | O17: 1.1355014 | P17: =C17/G17 -> 0 | Q17: =C17/F17 -> 0 | R17: =C17/H17 -> 0 | S17: =IF(C17>500,TRUE,FALSE) -> FALSE | T17: =IF(C17>750,TRUE,FALSE) -> FALSE | U17: =IF(C17>1000,TRUE,FALSE) -> FALSE | V17: =IF(D17>500,TRUE,FALSE) -> FALSE
A18: 105904 | B18: University of Utah Police Dept. - UT | C18: 35 | D18: 35 | E18: 53 | F18: 91 | G18: 45 | H18: 47 | I18: T10 | J18: Full VR | K18: 45644 | L18: 45891 | M18: Direct | N18: 7 | O18: 0.49450549 | P18: =C18/G18 -> 0.77777778 | Q18: =C18/F18 -> 0.38461538 | R18: =C18/H18 -> 0.74468085 | S18: =IF(C18>500,TRUE,FALSE) -> FALSE | T18: =IF(C18>750,TRUE,FALSE) -> FALSE | U18: =IF(C18>1000,TRUE,FALSE) -> FALSE | V18: =IF(D18>500,TRUE,FALSE) -> FALSE
A19: 106000 | B19: Atlanta Police Dept. - GA | C19: 645 | D19: 164 | E19: 1657 | F19: 2337 | G19: 1800 | H19: 2414 | I19: T10 | J19: Full VR | K19: 45436 | M19: Major | N19: 33 | O19: 0.77021823 | P19: =C19/G19 -> 0.35833333 | Q19: =C19/F19 -> 0.27599487 | R19: =C19/H19 -> 0.26719138 | S19: =IF(C19>500,TRUE,FALSE) -> TRUE | T19: =IF(C19>750,TRUE,FALSE) -> FALSE | U19: =IF(C19>1000,TRUE,FALSE) -> FALSE | V19: =IF(D19>500,TRUE,FALSE) -> FALSE
A20: 106139 | B20: San Diego State Univ. PD CSU campus - CA | C20: 0 | D20: 0 | E20: 50 | F20: 92 | G20: 50 | H20: 198 | I20: T10 | J20: Full VR | K20: 45506 | M20: Direct | N20: 6 | O20: 0.54347826 | P20: =C20/G20 -> 0 | Q20: =C20/F20 -> 0 | R20: =C20/H20 -> 0 | S20: =IF(C20>500,TRUE,FALSE) -> FALSE | T20: =IF(C20>750,TRUE,FALSE) -> FALSE | U20: =IF(C20>1000,TRUE,FALSE) -> FALSE | V20: =IF(D20>500,TRUE,FALSE) -> FALSE
A21: 106155 | B21: Phoenix Police Dept. - AZ | C21: 745 | D21: 5 | E21: 2903 | F21: 2850 | G21: 3183 | H21: 2975 | I21: T10 | J21: Full VR | K21: 45327 | M21: Major | N21: 8 | O21: 1.1168421 | P21: =C21/G21 -> 0.23405592 | Q21: =C21/F21 -> 0.26140351 | R21: =C21/H21 -> 0.25042017 | S21: =IF(C21>500,TRUE,FALSE) -> TRUE | T21: =IF(C21>750,TRUE,FALSE) -> FALSE | U21: =IF(C21>1000,TRUE,FALSE) -> FALSE | V21: =IF(D21>500,TRUE,FALSE) -> FALSE
A22: 106169 | B22: LOUISIANA STATE PENITENTIARY | C22: 16 | D22: 16 | E22: 1506 | F22: 20 | G22: 1 | H22: 20 | I22: T10 | J22: Full VR | K22: 45107 | M22: Major | N22: 26 | O22: 0.05 | P22: =C22/G22 -> 16 | Q22: =C22/F22 -> 0.8 | R22: =C22/H22 -> 0.8 | S22: =IF(C22>500,TRUE,FALSE) -> FALSE | T22: =IF(C22>750,TRUE,FALSE) -> FALSE | U22: =IF(C22>1000,TRUE,FALSE) -> FALSE | V22: =IF(D22>500,TRUE,FALSE) -> FALSE
A23: 106199 | B23: Greenburgh Police Dept. - NY | C23: 4 | D23: 4 | E23: 110 | F23: 62 | G23: 109 | H23: 72 | I23: T10 | J23: Full VR | K23: 45622 | M23: T1200 | N23: 34 | O23: 1.7580645 | P23: =C23/G23 -> 0.036697248 | Q23: =C23/F23 -> 0.064516129 | R23: =C23/H23 -> 0.055555556 | S23: =IF(C23>500,TRUE,FALSE) -> FALSE | T23: =IF(C23>750,TRUE,FALSE) -> FALSE | U23: =IF(C23>1000,TRUE,FALSE) -> FALSE | V23: =IF(D23>500,TRUE,FALSE) -> FALSE
A24: 106262 | B24: Manteca Police Dept. - CA | C24: 1 | D24: 1 | E24: 71 | F24: 82 | G24: 96 | H24: 84 | I24: T10 | J24: Full VR | K24: 45778 | L24: 45876 | M24: Direct | N24: 3 | O24: 1.1707317 | P24: =C24/G24 -> 0.010416667 | Q24: =C24/F24 -> 0.012195122 | R24: =C24/H24 -> 0.011904762 | S24: =IF(C24>500,TRUE,FALSE) -> FALSE | T24: =IF(C24>750,TRUE,FALSE) -> FALSE | U24: =IF(C24>1000,TRUE,FALSE) -> FALSE | V24: =IF(D24>500,TRUE,FALSE) -> FALSE
A25: 106273 | B25: Waushara County Sheriff's Office - WI | C25: 192 | D25: 99 | E25: 24 | F25: 30 | G25: 0 | H25: 34 | I25: T10 | J25: Full VR | K25: 45238 | M25: Inside | N25: 20 | O25: 0 | P25: 0 | Q25: =C25/F25 -> 6.4 | R25: =C25/H25 -> 5.6470588 | S25: =IF(C25>500,TRUE,FALSE) -> FALSE | T25: =IF(C25>750,TRUE,FALSE) -> FALSE | U25: =IF(C25>1000,TRUE,FALSE) -> FALSE | V25: =IF(D25>500,TRUE,FALSE) -> FALSE
A26: 106281 | B26: Laredo Police Dept. - TX | C26: 302 | D26: 302 | E26: 492 | F26: 200 | G26: 58 | H26: 309 | I26: T10 | J26: Taser Skills | K26: 45379 | M26: T1200 | N26: 4 | O26: 0.29 | P26: =C26/G26 -> 5.2068966 | Q26: =C26/F26 -> 1.51 | R26: =C26/H26 -> 0.97734628 | S26: =IF(C26>500,TRUE,FALSE) -> FALSE | T26: =IF(C26>750,TRUE,FALSE) -> FALSE | U26: =IF(C26>1000,TRUE,FALSE) -> FALSE | V26: =IF(D26>500,TRUE,FALSE) -> FALSE
A27: 106297 | B27: Springfield Police Department - MO | C27: 523 | D27: 27 | E27: 325 | F27: 235 | G27: 296 | H27: 242 | I27: T10 | J27: Full VR | K27: 45279 | M27: T1200 | N27: 21 | O27: 1.2595745 | P27: =C27/G27 -> 1.7668919 | Q27: =C27/F27 -> 2.2255319 | R27: =C27/H27 -> 2.161157 | S27: =IF(C27>500,TRUE,FALSE) -> TRUE | T27: =IF(C27>750,TRUE,FALSE) -> FALSE | U27: =IF(C27>1000,TRUE,FALSE) -> FALSE | V27: =IF(D27>500,TRUE,FALSE) -> FALSE
A28: 106304 | B28: Los Angeles County Sheriff's Dept. - HQ | C28: 457 | D28: 65 | E28: 10617 | F28: 3197 | G28: 6053 | H28: 3333 | I28: T10 | J28: Full VR | N28: 19 | O28: 1.8933375 | P28: =C28/G28 -> 0.075499752 | Q28: =C28/F28 -> 0.14294651 | R28: =C28/H28 -> 0.13711371 | S28: =IF(C28>500,TRUE,FALSE) -> FALSE | T28: =IF(C28>750,TRUE,FALSE) -> FALSE | U28: =IF(C28>1000,TRUE,FALSE) -> FALSE | V28: =IF(D28>500,TRUE,FALSE) -> FALSE
A29: 106338 | B29: Oregon State Police - OR | C29: 1269 | D29: 1269 | E29: 681 | F29: 750 | G29: 895 | H29: 775 | I29: T10 | J29: Full VR | K29: 45775 | L29: 45881 | M29: Major | N29: 4 | O29: 1.1933333 | P29: =C29/G29 -> 1.4178771 | Q29: =C29/F29 -> 1.692 | R29: =C29/H29 -> 1.6374194 | S29: =IF(C29>500,TRUE,FALSE) -> TRUE | T29: =IF(C29>750,TRUE,FALSE) -> TRUE | U29: =IF(C29>1000,TRUE,FALSE) -> TRUE | V29: =IF(D29>500,TRUE,FALSE) -> TRUE
A30: 106346 | B30: Seattle Police Dept. - WA | C30: 644 | D30: 54 | E30: 1282 | F30: 1200 | G30: 1340 | H30: 877 | I30: T10 | J30: Full VR | K30: 45106 | M30: Major | N30: 47 | O30: 1.1166667 | P30: =C30/G30 -> 0.48059701 | Q30: =C30/F30 -> 0.53666667 | R30: =C30/H30 -> 0.73432155 | S30: =IF(C30>500,TRUE,FALSE) -> TRUE | T30: =IF(C30>750,TRUE,FALSE) -> FALSE | U30: =IF(C30>1000,TRUE,FALSE) -> FALSE | V30: =IF(D30>500,TRUE,FALSE) -> FALSE
A31: 106436 | B31: North Palm Beach Police Department - FL | C31: 10 | D31: 5 | E31: 33 | F31: 41 | G31: 1 | H31: 42 | I31: T10 | J31: Full VR | K31: 45804 | L31: 45907 | M31: Inside | N31: 2 | O31: 0.024390244 | P31: =C31/G31 -> 10 | Q31: =C31/F31 -> 0.24390244 | R31: =C31/H31 -> 0.23809524 | S31: =IF(C31>500,TRUE,FALSE) -> FALSE | T31: =IF(C31>750,TRUE,FALSE) -> FALSE | U31: =IF(C31>1000,TRUE,FALSE) -> FALSE | V31: =IF(D31>500,TRUE,FALSE) -> FALSE
A32: 106442 | B32: Tomball Police Dept. - TX | C32: 48 | D32: 48 | E32: 45 | F32: 46 | G32: 64 | H32: 47 | I32: T10 | J32: Taser Skills | K32: 45726 | M32: Direct | N32: 5 | O32: 1.3913043 | P32: =C32/G32 -> 0.75 | Q32: =C32/F32 -> 1.0434783 | R32: =C32/H32 -> 1.0212766 | S32: =IF(C32>500,TRUE,FALSE) -> FALSE | T32: =IF(C32>750,TRUE,FALSE) -> FALSE | U32: =IF(C32>1000,TRUE,FALSE) -> FALSE | V32: =IF(D32>500,TRUE,FALSE) -> FALSE
A33: 106477 | B33: City of Rock Hill Police Dept - SC | C33: 2 | D33: 0 | E33: 150 | F33: 156 | G33: 158 | H33: 326 | I33: T10 | J33: Full VR | K33: 45279 | M33: T1200 | N33: 45 | O33: 1.0128205 | P33: =C33/G33 -> 0.012658228 | Q33: =C33/F33 -> 0.012820513 | R33: =C33/H33 -> 0.0061349693 | S33: =IF(C33>500,TRUE,FALSE) -> FALSE | T33: =IF(C33>750,TRUE,FALSE) -> FALSE | U33: =IF(C33>1000,TRUE,FALSE) -> FALSE | V33: =IF(D33>500,TRUE,FALSE) -> FALSE
A34: 106478 | B34: Fresno Police Dept. - CA | C34: 369 | D34: 355 | E34: 785 | F34: 800 | G34: 1286 | H34: 851 | I34: T10 | J34: Full VR | K34: 45302 | L34: 45686 | M34: Major | N34: 16 | O34: 1.6075 | P34: =C34/G34 -> 0.28693624 | Q34: =C34/F34 -> 0.46125 | R34: =C34/H34 -> 0.43360752 | S34: =IF(C34>500,TRUE,FALSE) -> FALSE | T34: =IF(C34>750,TRUE,FALSE) -> FALSE | U34: =IF(C34>1000,TRUE,FALSE) -> FALSE | V34: =IF(D34>500,TRUE,FALSE) -> FALSE
A35: 106509 | B35: Ontario Police Dept. - CA | C35: 9 | D35: 8 | E35: 260 | F35: 330 | G35: 341 | H35: 341 | I35: T10 | J35: Full VR | K35: 45833 | M35: T1200 | N35: 33 | O35: 1.0333333 | P35: =C35/G35 -> 0.026392962 | Q35: =C35/F35 -> 0.027272727 | R35: =C35/H35 -> 0.026392962 | S35: =IF(C35>500,TRUE,FALSE) -> FALSE | T35: =IF(C35>750,TRUE,FALSE) -> FALSE | U35: =IF(C35>1000,TRUE,FALSE) -> FALSE | V35: =IF(D35>500,TRUE,FALSE) -> FALSE
A36: 106516 | B36: Farmers Branch Police Dept. - TX | C36: 252 | D36: 34 | E36: 86 | F36: 80 | G36: 101 | H36: 82 | I36: T10 | J36: Full VR | K36: 45105 | M36: Direct | N36: 26 | O36: 1.2625 | P36: =C36/G36 -> 2.4950495 | Q36: =C36/F36 -> 3.15 | R36: =C36/H36 -> 3.0731707 | S36: =IF(C36>500,TRUE,FALSE) -> FALSE | T36: =IF(C36>750,TRUE,FALSE) -> FALSE | U36: =IF(C36>1000,TRUE,FALSE) -> FALSE | V36: =IF(D36>500,TRUE,FALSE) -> FALSE
A37: 106522 | B37: Hamilton County Sheriff's Office - OH | C37: 1775 | D37: 1775 | E37: 1027 | F37: 626 | G37: 690 | H37: 712 | I37: T10 | J37: Full VR | K37: 45623 | M37: Major | N37: 7 | O37: 1.1022364 | P37: =C37/G37 -> 2.5724638 | Q37: =C37/F37 -> 2.8354633 | R37: =C37/H37 -> 2.4929775 | S37: =IF(C37>500,TRUE,FALSE) -> TRUE | T37: =IF(C37>750,TRUE,FALSE) -> TRUE | U37: =IF(C37>1000,TRUE,FALSE) -> TRUE | V37: =IF(D37>500,TRUE,FALSE) -> TRUE
A38: 106524 | B38: Weld County Sheriff's Office - CO | C38: 1297 | D38: 207 | E38: 82 | F38: 329 | G38: 335 | H38: 259 | I38: T10 | J38: Full VR | K38: 45637 | L38: 45728 | M38: Direct | N38: 9 | O38: 1.0182371 | P38: =C38/G38 -> 3.8716418 | Q38: =C38/F38 -> 3.9422492 | R38: =C38/H38 -> 5.007722 | S38: =IF(C38>500,TRUE,FALSE) -> TRUE | T38: =IF(C38>750,TRUE,FALSE) -> TRUE | U38: =IF(C38>1000,TRUE,FALSE) -> TRUE | V38: =IF(D38>500,TRUE,FALSE) -> FALSE
A39: 106525 | B39: Evergreen State College Police Dept - WA | C39: 4 | D39: 4 | E39: 9 | F39: 9 | G39: 0 | H39: 9 | I39: T10 | J39: Taser Skills | K39: 45833 | L39: 45957 | M39: Inside | N39: 2 | O39: 0 | P39: 0 | Q39: =C39/F39 -> 0.44444444 | R39: =C39/H39 -> 0.44444444 | S39: =IF(C39>500,TRUE,FALSE) -> FALSE | T39: =IF(C39>750,TRUE,FALSE) -> FALSE | U39: =IF(C39>1000,TRUE,FALSE) -> FALSE | V39: =IF(D39>500,TRUE,FALSE) -> FALSE
A40: 106528 | B40: Port of Seattle Police Dept. - WA | C40: 518 | D40: 510 | E40: 109 | F40: 150 | G40: 120 | H40: 155 | I40: T10 | J40: Full VR | K40: 45657 | L40: 45784 | M40: T1200 | N40: 7 | O40: 0.8 | P40: =C40/G40 -> 4.3166667 | Q40: =C40/F40 -> 3.4533333 | R40: =C40/H40 -> 3.3419355 | S40: =IF(C40>500,TRUE,FALSE) -> TRUE | T40: =IF(C40>750,TRUE,FALSE) -> FALSE | U40: =IF(C40>1000,TRUE,FALSE) -> FALSE | V40: =IF(D40>500,TRUE,FALSE) -> TRUE
...

Sheet Meeting Threshold
A1: Account Number | B1: Account Name | C1: T12 SIM Usage | D1: T6 SIM Completions | E1: Number of Officers | F1: Active License Quantity | G1: Footprint Size | H1: Total T10 CEWs | I1: TASER Type | J1: Active License Type | K1: VR HW Purchase Date | L1: First PSO Start Date | M1: Account Line Size | N1: Time as Customer | O1: Footprint Difference | P1: Threshold - Footprint | Q1: Threshold - License | R1: Threshold - CEW | S1: 500+ Events | T1: 750+ Events | U1: 1000+ Events | V1: T6 500+ Events
A2: 114601 | B2: Baltimore County Police Dept. - MD | C2: 5255 | D2: 5055 | E2: 1856 | F2: 1703 | G2: 2194 | H2: 1136 | I2: T10 | J2: Full VR | K2: 45621 | L2: 45720 | M2: Major | N2: 10 | O2: 1.29 | P2: 2.4 | Q2: 3.09 | R2: 4.63 | S2: TRUE | T2: TRUE | U2: TRUE | V2: TRUE
A3: 105469 | B3: San Bernardino County Sheriff's Dept. - CA | C3: 4462 | D3: 1025 | E3: 2385 | F3: 1000 | G3: 950 | H3: 2066 | I3: T10 | J3: Full VR | K3: 45596 | L3: 45713 | M3: Major | N3: 10 | O3: 0.95 | P3: 4.7 | Q3: 4.46 | R3: 2.16 | S3: TRUE | T3: TRUE | U3: TRUE | V3: TRUE
A4: 116660 | B4: Albuquerque Police Dept. - NM | C4: 3166 | D4: 2807 | E4: 997 | F4: 1260 | G4: 1335 | H4: 2480 | I4: T10 | J4: Full VR | K4: 45195 | L4: 45737 | M4: Major | N4: 10 | O4: 1.06 | P4: 2.37 | Q4: 2.51 | R4: 1.28 | S4: TRUE | T4: TRUE | U4: TRUE | V4: TRUE
A5: 108541 | B5: Maryland State Police - MD | C5: 3055 | D5: 1543 | E5: 1441 | F5: 750 | G5: 2325 | H5: 800 | I5: T10 | J5: Full VR | K5: 45258 | L5: 45694 | M5: Major | N5: 11 | O5: 3.1 | P5: 1.31 | Q5: 4.07 | R5: 3.82 | S5: TRUE | T5: TRUE | U5: TRUE | V5: TRUE
A6: 114073 | B6: Texas Department of Public Safety - TX | C6: 2998 | D6: 2402 | E6: 4060 | F6: 2750 | G6: 1328 | H6: 3875 | I6: T10 | J6: Full VR | K6: 45392 | L6: 45762 | M6: Major | N6: 12 | O6: 0.48 | P6: 2.26 | Q6: 1.09 | R6: 0.77 | S6: TRUE | T6: TRUE | U6: TRUE | V6: TRUE
A7: 113118 | B7: Oklahoma City Police Dept. - OK | C7: 2744 | D7: 780 | E7: 1141 | F7: 700 | G7: 1458 | H7: 723 | I7: T10 | J7: Full VR | K7: 45580 | M7: Major | N7: 49 | O7: 2.08 | P7: 1.88 | Q7: 3.92 | R7: 3.8 | S7: TRUE | T7: TRUE | U7: TRUE | V7: TRUE
A8: 105785 | B8: Fort Worth Police Department - TX | C8: 2323 | D8: 2003 | E8: 1717 | F8: 3861 | G8: 1993 | H8: 1904 | I8: T10 | J8: Full VR | K8: 45048 | M8: Major | N8: 45 | O8: 0.52 | P8: 1.17 | Q8: 0.6 | R8: 1.22 | S8: TRUE | T8: TRUE | U8: TRUE | V8: TRUE
A9: 108658 | B9: Travis County Sheriff's Office - TX | C9: 2220 | D9: 2304 | E9: 1198 | F9: 763 | G9: 1532 | H9: 761 | I9: T10 | J9: Full VR | K9: 45726 | L9: 45797 | M9: Major | N9: 6 | O9: 2.01 | P9: 1.45 | Q9: 2.91 | R9: 2.92 | S9: TRUE | T9: TRUE | U9: TRUE | V9: TRUE
A10: 124496 | B10: Pittsburgh Bureau of Police - PA | C10: 2215 | D10: 270 | E10: 965 | F10: 900 | G10: 992 | H10: 930 | I10: T10 | J10: Full VR | K10: 45107 | M10: Major | N10: 28 | O10: 1.1 | P10: 2.23 | Q10: 2.46 | R10: 2.38 | S10: TRUE | T10: TRUE | U10: TRUE | V10: FALSE
A11: 107750 | B11: New Mexico Dept. of Public Safety - NM | C11: 2186 | D11: 163 | E11: 682 | F11: 715 | G11: 745 | H11: 620 | I11: T10 | J11: Full VR | K11: 45184 | M11: Major | N11: 25 | O11: 1.04 | P11: 2.93 | Q11: 3.06 | R11: 3.53 | S11: TRUE | T11: TRUE | U11: TRUE | V11: FALSE
A12: 113410 | B12: Anaheim Police Dept. - CA | C12: 2079 | D12: 50 | E12: 385 | F12: 457 | G12: 552 | H12: 428 | I12: T10 | J12: Full VR | K12: 45656 | M12: T1200 | N12: 34 | O12: 1.21 | P12: 3.77 | Q12: 4.55 | R12: 4.86 | S12: TRUE | T12: TRUE | U12: TRUE | V12: FALSE
A13: 108053 | B13: Williamson County Sheriff's Office - TN | C13: 1995 | D13: 1321 | E13: 199 | F13: 243 | G13: 3 | H13: 302 | I13: T10 | J13: Full VR | K13: 45461 | M13: T1200 | N13: 40 | O13: 0.01 | P13: 665 | Q13: 8.21 | R13: 6.61 | S13: TRUE | T13: TRUE | U13: TRUE | V13: TRUE
A14: 108467 | B14: Charlotte County Sheriff's Office - FL | C14: 1961 | D14: 2152 | E14: 445 | F14: 488 | G14: 230 | H14: 411 | I14: T10 | J14: Full VR | K14: 45686 | L14: 45792 | M14: T1200 | N14: 6 | O14: 0.47 | P14: 8.53 | Q14: 4.02 | R14: 4.77 | S14: TRUE | T14: TRUE | U14: TRUE | V14: TRUE
A15: 109245 | B15: Clay County Sheriff's Office - FL | C15: 1910 | D15: 1910 | E15: 408 | F15: 350 | G15: 426 | H15: 663 | I15: T10 | J15: Full VR | K15: 45688 | L15: 45848 | M15: T1200 | N15: 4 | O15: 1.22 | P15: 4.48 | Q15: 5.46 | R15: 2.88 | S15: TRUE | T15: TRUE | U15: TRUE | V15: TRUE
A16: 175721 | B16: Boston Police Dept. - MA | C16: 1854 | D16: 861 | E16: 2119 | F16: 1570 | G16: 2200 | H16: 1622 | I16: T10 | J16: Full VR | K16: 45260 | L16: 45692 | M16: Major | N16: 23 | O16: 1.4 | P16: 0.84 | Q16: 1.18 | R16: 1.14 | S16: TRUE | T16: TRUE | U16: TRUE | V16: TRUE
A17: 110619 | B17: Joliet Police Dept. - IL | C17: 1781 | D17: 1260 | E17: 286 | F17: 286 | G17: 375 | H17: 295 | I17: T10 | J17: Full VR | K17: 45261 | M17: T1200 | N17: 57 | O17: 1.31 | P17: 4.75 | Q17: 6.23 | R17: 6.04 | S17: TRUE | T17: TRUE | U17: TRUE | V17: TRUE
A18: 106522 | B18: Hamilton County Sheriff's Office - OH | C18: 1775 | D18: 1775 | E18: 1027 | F18: 626 | G18: 690 | H18: 712 | I18: T10 | J18: Full VR | K18: 45623 | M18: Major | N18: 7 | O18: 1.1 | P18: 2.57 | Q18: 2.84 | R18: 2.49 | S18: TRUE | T18: TRUE | U18: TRUE | V18: TRUE
A19: 123242 | B19: Whitfield County Sheriff's Office - GA | C19: 1737 | D19: 1128 | E19: 171 | F19: 430 | G19: 117 | H19: 154 | I19: T10 | J19: Full VR | K19: 45827 | M19: T1200 | N19: 3 | O19: 0.27 | P19: 14.85 | Q19: 4.04 | R19: 11.28 | S19: TRUE | T19: TRUE | U19: TRUE | V19: TRUE
A20: 302836 | B20: San Bernardino County Probation Dept. - CA | C20: 1682 | D20: 1682 | E20: 503 | F20: 505 | G20: 8 | H20: 516 | I20: T10 | J20: Full VR | K20: 45720 | L20: 45832 | M20: Major | N20: 7 | O20: 0.02 | P20: 210.25 | Q20: 3.33 | R20: 3.26 | S20: TRUE | T20: TRUE | U20: TRUE | V20: TRUE
A21: 124615 | B21: Auburn Police Dept - AL | C21: 1680 | D21: 1364 | E21: 148 | F21: 120 | G21: 148 | H21: 124 | I21: T10 | J21: Full VR | K21: 45532 | M21: T1200 | N21: 51 | O21: 1.23 | P21: 11.35 | Q21: 14 | R21: 13.55 | S21: TRUE | T21: TRUE | U21: TRUE | V21: TRUE
A22: 110637 | B22: Shreveport Police Dept - LA | C22: 1595 | D22: 570 | E22: 531 | F22: 480 | G22: 505 | H22: 465 | I22: T10 | J22: Full VR | K22: 45289 | M22: T1200 | N22: 16 | O22: 1.05 | P22: 3.16 | Q22: 3.32 | R22: 3.43 | S22: TRUE | T22: TRUE | U22: TRUE | V22: TRUE
A23: 323664 | B23: Louisiana Department of Corrections - LA | C23: 1531 | D23: 1398 | E23: 611 | F23: 1335 | G23: 1240 | H23: 973 | I23: T10 | J23: Full VR | K23: 45655 | L23: 45747 | M23: Major | N23: 12 | O23: 0.93 | P23: 1.23 | Q23: 1.15 | R23: 1.57 | S23: TRUE | T23: TRUE | U23: TRUE | V23: TRUE
A24: 128775 | B24: Brevard County Sheriff's Office - FL | C24: 1498 | D24: 420 | E24: 586 | F24: 586 | G24: 12 | H24: 605 | I24: T10 | J24: Full VR | K24: 45469 | M24: Major | N24: 12 | O24: 0.02 | P24: 124.83 | Q24: 2.56 | R24: 2.48 | S24: TRUE | T24: TRUE | U24: TRUE | V24: FALSE
A25: 107092 | B25: Seminole County Sheriff's Office - FL | C25: 1468 | D25: 1356 | E25: 701 | F25: 750 | G25: 570 | H25: 567 | I25: T10 | J25: Full VR | K25: 45194 | M25: Major | N25: 38 | O25: 0.76 | P25: 2.58 | Q25: 1.96 | R25: 2.59 | S25: TRUE | T25: TRUE | U25: TRUE | V25: TRUE
A26: 109479 | B26: Naperville Police Dept. - IL | C26: 1427 | D26: 81 | E26: 199 | F26: 265 | G26: 205 | H26: 206 | I26: T10 | J26: Full VR | K26: 45561 | L26: 45694 | M26: T1200 | N26: 9 | O26: 0.77 | P26: 6.96 | Q26: 5.38 | R26: 6.93 | S26: TRUE | T26: TRUE | U26: TRUE | V26: FALSE
A27: 112474 | B27: Pinellas County Sheriff's Office - FL | C27: 1424 | D27: 895 | E27: 1422 | F27: 1110 | G27: 950 | H27: 1146 | I27: T10 | J27: Full VR | K27: 45288 | M27: Major | N27: 22 | O27: 0.86 | P27: 1.5 | Q27: 1.28 | R27: 1.24 | S27: TRUE | T27: TRUE | U27: TRUE | V27: TRUE
A28: 110958 | B28: Walton County Sheriff's Office - GA | C28: 1420 | D28: 1351 | E28: 167 | F28: 250 | G28: 5 | H28: 206 | I28: T10 | J28: Full VR | K28: 45616 | L28: 45702 | M28: T1200 | N28: 9 | O28: 0.02 | P28: 284 | Q28: 5.68 | R28: 6.89 | S28: TRUE | T28: TRUE | U28: TRUE | V28: TRUE
A29: 109160 | B29: North Carolina State Highway Patrol - NC | C29: 1320 | D29: 970 | E29: 1715 | F29: 1450 | G29: 120 | H29: 1585 | I29: T10 | J29: Full VR | K29: 45230 | M29: Major | N29: 33 | O29: 0.08 | P29: 11 | Q29: 0.91 | R29: 0.83 | S29: TRUE | T29: TRUE | U29: TRUE | V29: TRUE
A30: 106524 | B30: Weld County Sheriff's Office - CO | C30: 1297 | D30: 207 | E30: 82 | F30: 329 | G30: 335 | H30: 259 | I30: T10 | J30: Full VR | K30: 45637 | L30: 45728 | M30: Direct | N30: 9 | O30: 1.02 | P30: 3.87 | Q30: 3.94 | R30: 5.01 | S30: TRUE | T30: TRUE | U30: TRUE | V30: FALSE
A31: 107824 | B31: Jefferson County Sheriff's Office - CO | C31: 1273 | D31: 987 | E31: 667 | F31: 705 | G31: 565 | H31: 361 | I31: T10 | J31: Full VR | K31: 45642 | L31: 45742 | M31: Major | N31: 10 | O31: 0.8 | P31: 2.25 | Q31: 1.81 | R31: 3.53 | S31: TRUE | T31: TRUE | U31: TRUE | V31: TRUE
A32: 106338 | B32: Oregon State Police - OR | C32: 1269 | D32: 1269 | E32: 681 | F32: 750 | G32: 895 | H32: 775 | I32: T10 | J32: Full VR | K32: 45775 | L32: 45881 | M32: Major | N32: 4 | O32: 1.19 | P32: 1.42 | Q32: 1.69 | R32: 1.64 | S32: TRUE | T32: TRUE | U32: TRUE | V32: TRUE
A33: 111064 | B33: Lake County Sheriff's Office - FL | C33: 1264 | D33: 1017 | E33: 470 | F33: 933 | G33: 327 | H33: 453 | I33: T10 | J33: Full VR | K33: 45373 | M33: T1200 | N33: 18 | O33: 0.35 | P33: 3.87 | Q33: 1.35 | R33: 2.79 | S33: TRUE | T33: TRUE | U33: TRUE | V33: TRUE
A34: 111178 | B34: St. Charles Police Dept. - MO | C34: 1154 | D34: 1154 | E34: 113 | F34: 265 | G34: 105 | H34: 131 | I34: T10 | J34: Full VR | K34: 45740 | L34: 45853 | M34: T1200 | N34: 6 | O34: 0.4 | P34: 10.99 | Q34: 4.35 | R34: 8.81 | S34: TRUE | T34: TRUE | U34: TRUE | V34: TRUE
A35: 313790 | B35: Tuscaloosa Police Dept. - AL | C35: 1119 | D35: 48 | E35: 289 | F35: 150 | G35: 295 | H35: 155 | I35: T10 | J35: Full VR | K35: 45560 | L35: 45615 | M35: T1200 | N35: 13 | O35: 1.97 | P35: 3.79 | Q35: 7.46 | R35: 7.22 | S35: TRUE | T35: TRUE | U35: TRUE | V35: FALSE
A36: 109867 | B36: Manatee County Sheriff's Office - FL | C36: 1119 | D36: 1118 | E36: 723 | F36: 1630 | G36: 558 | H36: 826 | I36: T10 | J36: Full VR | K36: 45744 | L36: 45868 | M36: Major | N36: 11 | O36: 0.34 | P36: 2.01 | Q36: 0.69 | R36: 1.35 | S36: TRUE | T36: TRUE | U36: TRUE | V36: TRUE
A37: 109291 | B37: Boulder Police Dept. - CO | C37: 1070 | D37: 1051 | E37: 182 | F37: 600 | G37: 210 | H37: 206 | I37: T10 | J37: Full VR | K37: 45870 | L37: 45912 | M37: T1200 | N37: 22 | O37: 0.35 | P37: 5.1 | Q37: 1.78 | R37: 5.19 | S37: TRUE | T37: TRUE | U37: TRUE | V37: TRUE
A38: 106715 | B38: Terrebonne Parish Sheriff's Office - LA | C38: 1070 | D38: 726 | E38: 275 | F38: 136 | G38: 186 | H38: 140 | I38: T10 | J38: Full VR | K38: 45194 | M38: T1200 | N38: 19 | O38: 1.37 | P38: 5.75 | Q38: 7.87 | R38: 7.64 | S38: TRUE | T38: TRUE | U38: TRUE | V38: TRUE
A39: 408831 | B39: Santa Clara County Sheriff's Office - CA | C39: 1060 | D39: 541 | E39: 1285 | F39: 1275 | G39: 0 | H39: 77 | I39: T10 | J39: Full VR | K39: 45616 | L39: 45659 | M39: Major | N39: 12 | O39: 0 | P39: 0 | Q39: 0.83 | R39: 13.77 | S39: TRUE | T39: TRUE | U39: TRUE | V39: TRUE
A40: 511036 | B40: Will County Sheriff Office Enforcement - IL | C40: 1056 | D40: 1040 | E40: 233 | F40: 240 | G40: 231 | H40: 248 | I40: T10 | J40: Full VR | K40: 45266 | M40: T1200 | N40: 21 | O40: 0.96 | P40: 4.57 | Q40: 4.4 | R40: 4.26 | S40: TRUE | T40: TRUE | U40: TRUE | V40: TRUE
...

Sheet Notables Not Meeting Threshold
A1: Account Number | B1: Account Name | C1: T12 SIM Usage | D1: T6 SIM Completions | E1: Active License Quantity | F1: Footprint Size | G1: Threshold - License | H1: 500+ Events | I1: 750+ Events | J1: 1000+ Events | K1: T6 500+ Events
A2: 108490 | B2: HILLSBOROUGH CO SHERIFF'S OFFICE - FL | C2: 2047 | D2: 33 | E2: 5758 | F2: 2088 | G2: =C2/E2 -> 0.35550538 | H2: =IF(C2>500,TRUE,FALSE) -> TRUE | I2: =IF(C2>750,TRUE,FALSE) -> TRUE | J2: =IF(C2>1000,TRUE,FALSE) -> TRUE | K2: =IF(D2>500,TRUE,FALSE) -> FALSE
A3: 108050 | B3: Metro Nashville Police Department -TN | C3: 1993 | D3: 270 | E3: 1658 | F3: 1400 | G3: =C3/E3 -> 1.2020507 | H3: =IF(C3>500,TRUE,FALSE) -> TRUE | I3: =IF(C3>750,TRUE,FALSE) -> TRUE | J3: =IF(C3>1000,TRUE,FALSE) -> TRUE | K3: =IF(D3>500,TRUE,FALSE) -> FALSE
A4: 328079 | B4: Detroit Police Dept. - MI | C4: 1714 | D4: 328 | E4: 3450 | F4: 96 | G4: =C4/E4 -> 0.49681159 | H4: =IF(C4>500,TRUE,FALSE) -> TRUE | I4: =IF(C4>750,TRUE,FALSE) -> TRUE | J4: =IF(C4>1000,TRUE,FALSE) -> TRUE | K4: =IF(D4>500,TRUE,FALSE) -> FALSE
A5: 108787 | B5: Omaha Police Dept - NE | C5: 869 | D5: 57 | E5: 1231 | F5: 718 | G5: =C5/E5 -> 0.70593014 | H5: =IF(C5>500,TRUE,FALSE) -> TRUE | I5: =IF(C5>750,TRUE,FALSE) -> TRUE | J5: =IF(C5>1000,TRUE,FALSE) -> FALSE | K5: =IF(D5>500,TRUE,FALSE) -> FALSE
A6: 327797 | B6: Philadelphia Police Dept. - PA | C6: 773 | D6: 443 | E6: 9000 | F6: 4184 | G6: =C6/E6 -> 0.085888889 | H6: =IF(C6>500,TRUE,FALSE) -> TRUE | I6: =IF(C6>750,TRUE,FALSE) -> TRUE | J6: =IF(C6>1000,TRUE,FALSE) -> FALSE | K6: =IF(D6>500,TRUE,FALSE) -> FALSE
A7: 106155 | B7: Phoenix Police Dept. - AZ | C7: 745 | D7: 5 | E7: 2850 | F7: 3183 | G7: =C7/E7 -> 0.26140351 | H7: =IF(C7>500,TRUE,FALSE) -> TRUE | I7: =IF(C7>750,TRUE,FALSE) -> FALSE | J7: =IF(C7>1000,TRUE,FALSE) -> FALSE | K7: =IF(D7>500,TRUE,FALSE) -> FALSE
A8: 105702 | B8: Tampa Police Department - FL | C8: 719 | D8: 474 | E8: 1350 | F8: 928 | G8: =C8/E8 -> 0.53259259 | H8: =IF(C8>500,TRUE,FALSE) -> TRUE | I8: =IF(C8>750,TRUE,FALSE) -> FALSE | J8: =IF(C8>1000,TRUE,FALSE) -> FALSE | K8: =IF(D8>500,TRUE,FALSE) -> FALSE
A9: 451087 | B9: Richardson Police Department - TX | C9: 707 | D9: 459 | E9: 955 | F9: 191 | G9: =C9/E9 -> 0.74031414 | H9: =IF(C9>500,TRUE,FALSE) -> TRUE | I9: =IF(C9>750,TRUE,FALSE) -> FALSE | J9: =IF(C9>1000,TRUE,FALSE) -> FALSE | K9: =IF(D9>500,TRUE,FALSE) -> FALSE
A10: 106000 | B10: Atlanta Police Dept. - GA | C10: 645 | D10: 164 | E10: 2337 | F10: 1800 | G10: =C10/E10 -> 0.27599487 | H10: =IF(C10>500,TRUE,FALSE) -> TRUE | I10: =IF(C10>750,TRUE,FALSE) -> FALSE | J10: =IF(C10>1000,TRUE,FALSE) -> FALSE | K10: =IF(D10>500,TRUE,FALSE) -> FALSE
A11: 106346 | B11: Seattle Police Dept. - WA | C11: 644 | D11: 54 | E11: 1200 | F11: 1340 | G11: =C11/E11 -> 0.53666667 | H11: =IF(C11>500,TRUE,FALSE) -> TRUE | I11: =IF(C11>750,TRUE,FALSE) -> FALSE | J11: =IF(C11>1000,TRUE,FALSE) -> FALSE | K11: =IF(D11>500,TRUE,FALSE) -> FALSE
A12: 112305 | B12: Virginia Beach Police Dept. - VA | C12: 642 | D12: 93 | E12: 1626 | F12: 888 | G12: =C12/E12 -> 0.39483395 | H12: =IF(C12>500,TRUE,FALSE) -> TRUE | I12: =IF(C12>750,TRUE,FALSE) -> FALSE | J12: =IF(C12>1000,TRUE,FALSE) -> FALSE | K12: =IF(D12>500,TRUE,FALSE) -> FALSE
A13: 126746 | B13: Mississippi Highway Patrol - MS | C13: 535 | D13: 91 | E13: 516 | F13: 0 | G13: =C13/E13 -> 1.0368217 | H13: =IF(C13>500,TRUE,FALSE) -> TRUE | I13: =IF(C13>750,TRUE,FALSE) -> FALSE | J13: =IF(C13>1000,TRUE,FALSE) -> FALSE | K13: =IF(D13>500,TRUE,FALSE) -> FALSE
... A18: 119697 | B18: Pasadena Police Dept. - TX | C18: 353 | D18: 348 | E18: 425 | F18: 3 | G18: =C18/E18 -> 0.83058824 | H18: =IF(C18>500,TRUE,FALSE) -> FALSE | I18: =IF(C18>750,TRUE,FALSE) -> FALSE | J18: =IF(C18>1000,TRUE,FALSE) -> FALSE | K18: =IF(D18>500,TRUE,FALSE) -> FALSE
A19: CA0115409 | B19: Peel Regional Police Service - CAN | C19: 337 | D19: 337 | E19: 750 | F19: 2119 | G19: =C19/E19 -> 0.44933333 | H19: =IF(C19>500,TRUE,FALSE) -> FALSE | I19: =IF(C19>750,TRUE,FALSE) -> FALSE | J19: =IF(C19>1000,TRUE,FALSE) -> FALSE | K19: =IF(D19>500,TRUE,FALSE) -> FALSE

Sheet All Agencies
A1: Account Number | B1: Account Name | C1: T12 SIM Usage | D1: T6 SIM Completions | E1: Number of Officers | F1: Active License Quantity | G1: Footprint Size | H1: Total CEWs | I1: TASER Type | J1: Active License Type | K1: VR HW Purchase Date | L1: First PSO Start Date | M1: Account Line Size | N1: Time as Customer
A2: 114601 | B2: Baltimore County Police Dept. - MD | C2: 5255 | D2: 5055 | E2: 1856 | F2: 1703 | G2: 2194 | H2: 1136 | I2: T10 | J2: Full VR | K2: 45621 | L2: 45720 | M2: Major | N2: 10
A3: 105469 | B3: San Bernardino County Sheriff's Dept. - CA | C3: 4462 | D3: 1025 | E3: 2385 | F3: 1000 | G3: 950 | H3: 2066 | I3: T10 | J3: Full VR | K3: 45596 | L3: 45713 | M3: Major | N3: 10
A4: 116660 | B4: Albuquerque Police Dept. - NM | C4: 3166 | D4: 2807 | E4: 997 | F4: 1260 | G4: 1335 | H4: 2480 | I4: T10 | J4: Full VR | K4: 45195 | L4: 45737 | M4: Major | N4: 10
A5: 108541 | B5: Maryland State Police - MD | C5: 3055 | D5: 1543 | E5: 1441 | F5: 750 | G5: 2325 | H5: 800 | I5: T10 | J5: Full VR | K5: 45258 | L5: 45694 | M5: Major | N5: 11
A6: 114073 | B6: Texas Department of Public Safety - TX | C6: 2998 | D6: 2402 | E6: 4060 | F6: 2750 | G6: 1328 | H6: 3875 | I6: T10 | J6: Full VR | K6: 45392 | L6: 45762 | M6: Major | N6: 12
A7: 113118 | B7: Oklahoma City Police Dept. - OK | C7: 2744 | D7: 780 | E7: 1141 | F7: 700 | G7: 1458 | H7: 723 | I7: T10 | J7: Full VR | K7: 45580 | M7: Major | N7: 49
A8: 105785 | B8: Fort Worth Police Department - TX | C8: 2323 | D8: 2003 | E8: 1717 | F8: 3861 | G8: 1993 | H8: 1904 | I8: T10 | J8: Full VR | K8: 45048 | M8: Major | N8: 45
A9: 108658 | B9: Travis County Sheriff's Office - TX | C9: 2220 | D9: 2304 | E9: 1198 | F9: 763 | G9: 1532 | H9: 761 | I9: T10 | J9: Full VR | K9: 45726 | L9: 45797 | M9: Major | N9: 6
A10: 124496 | B10: Pittsburgh Bureau of Police - PA | C10: 2215 | D10: 270 | E10: 965 | F10: 900 | G10: 992 | H10: 930 | I10: T10 | J10: Full VR | K10: 45107 | M10: Major | N10: 28
A11: 107750 | B11: New Mexico Dept. of Public Safety - NM | C11: 2186 | D11: 163 | E11: 682 | F11: 715 | G11: 745 | H11: 620 | I11: T10 | J11: Full VR | K11: 45184 | M11: Major | N11: 25
A12: 113410 | B12: Anaheim Police Dept. - CA | C12: 2079 | D12: 50 | E12: 385 | F12: 457 | G12: 552 | H12: 428 | I12: T10 | J12: Full VR | K12: 45656 | M12: T1200 | N12: 34
A13: 108490 | B13: HILLSBOROUGH CO SHERIFF'S OFFICE - FL | C13: 2047 | D13: 33 | E13: 1238 | F13: 5758 | G13: 2088 | H13: 3665 | I13: T10 | J13: Full VR | K13: 45473 | M13: Major | N13: 11
A14: 108053 | B14: Williamson County Sheriff's Office - TN | C14: 1995 | D14: 1321 | E14: 199 | F14: 243 | G14: 3 | H14: 302 | I14: T10 | J14: Full VR | K14: 45461 | M14: T1200 | N14: 40
A15: 108050 | B15: Metro Nashville Police Department -TN | C15: 1993 | D15: 270 | E15: 1508 | F15: 1658 | G15: 1400 | H15: 1713 | I15: T10 | J15: Full VR | K15: 45470 | M15: Major | N15: 44
A16: 108467 | B16: Charlotte County Sheriff's Office - FL | C16: 1961 | D16: 2152 | E16: 445 | F16: 488 | G16: 230 | H16: 411 | I16: T10 | J16: Full VR | K16: 45686 | L16: 45792 | M16: T1200 | N16: 6
A17: 109182 | B17: Metropolitan Transportation Authority PD - NY | C17: 1940 | D17: 1158 | E17: 695 | F17: 2095 | G17: 1156 | H17: 1033 | I17: T 7 | J17: Full VR | K17: 45273 | M17: Major | N17: 48
A18: 110010 | B18: Palm Beach County Sheriff's Office - FL | C18: 1919 | D18: 1088 | E18: 2170 | F18: 1739 | G18: 2000 | H18: 1239 | I18: T 7 | J18: Full VR | K18: 45273 | L18: 46007 | M18: Major | N18: 35
A19: 109245 | B19: Clay County Sheriff's Office - FL | C19: 1910 | D19: 1910 | E19: 408 | F19: 350 | G19: 426 | H19: 663 | I19: T10 | J19: Full VR | K19: 45688 | L19: 45848 | M19: T1200 | N19: 4
A20: 175721 | B20: Boston Police Dept. - MA | C20: 1854 | D20: 861 | E20: 2119 | F20: 1570 | G20: 2200 | H20: 1622 | I20: T10 | J20: Full VR | K20: 45260 | L20: 45692 | M20: Major | N20: 23
A21: 110619 | B21: Joliet Police Dept. - IL | C21: 1781 | D21: 1260 | E21: 286 | F21: 286 | G21: 375 | H21: 295 | I21: T10 | J21: Full VR | K21: 45261 | M21: T1200 | N21: 57
A22: 106522 | B22: Hamilton County Sheriff's Office - OH | C22: 1775 | D22: 1775 | E22: 1027 | F22: 626 | G22: 690 | H22: 712 | I22: T10 | J22: Full VR | K22: 45623 | M22: Major | N22: 7
A23: 123242 | B23: Whitfield County Sheriff's Office - GA | C23: 1737 | D23: 1128 | E23: 171 | F23: 430 | G23: 117 | H23: 154 | I23: T10 | J23: Full VR | K23: 45827 | M23: T1200 | N23: 3
A24: 106936 | B24: Charlotte - Mecklenburg Police Dept. - NC | C24: 1728 | D24: 202 | E24: 1760 | F24: 1750 | G24: 2010 | H24: 12 | I24: T 7 | J24: Full VR | K24: 45239 | M24: Major | N24: 43
A25: 328079 | B25: Detroit Police Dept. - MI | C25: 1714 | D25: 328 | E25: 2527 | F25: 3450 | G25: 96 | H25: 2583 | I25: T10 | J25: Full VR | K25: 45267 | M25: Major | N25: 22
A26: 302836 | B26: San Bernardino County Probation Dept. - CA | C26: 1682 | D26: 1682 | E26: 503 | F26: 505 | G26: 8 | H26: 516 | I26: T10 | J26: Full VR | K26: 45720 | L26: 45832 | M26: Major | N26: 7
A27: 124615 | B27: Auburn Police Dept - AL | C27: 1680 | D27: 1364 | E27: 148 | F27: 120 | G27: 148 | H27: 124 | I27: T10 | J27: Full VR | K27: 45532 | M27: T1200 | N27: 51
A28: 110637 | B28: Shreveport Police Dept - LA | C28: 1595 | D28: 570 | E28: 531 | F28: 480 | G28: 505 | H28: 465 | I28: T10 | J28: Full VR | K28: 45289 | M28: T1200 | N28: 16
A29: 323664 | B29: Louisiana Department of Corrections - LA | C29: 1531 | D29: 1398 | E29: 611 | F29: 1335 | G29: 1240 | H29: 973 | I29: T10 | J29: Full VR | K29: 45655 | L29: 45747 | M29: Major | N29: 12
A30: 128775 | B30: Brevard County Sheriff's Office - FL | C30: 1498 | D30: 420 | E30: 586 | F30: 586 | G30: 12 | H30: 605 | I30: T10 | J30: Full VR | K30: 45469 | M30: Major | N30: 12
A31: 107092 | B31: Seminole County Sheriff's Office - FL | C31: 1468 | D31: 1356 | E31: 701 | F31: 750 | G31: 570 | H31: 567 | I31: T10 | J31: Full VR | K31: 45194 | M31: Major | N31: 38
A32: 109479 | B32: Naperville Police Dept. - IL | C32: 1427 | D32: 81 | E32: 199 | F32: 265 | G32: 205 | H32: 206 | I32: T10 | J32: Full VR | K32: 45561 | L32: 45694 | M32: T1200 | N32: 9
A33: 112474 | B33: Pinellas County Sheriff's Office - FL | C33: 1424 | D33: 895 | E33: 1422 | F33: 1110 | G33: 950 | H33: 1146 | I33: T10 | J33: Full VR | K33: 45288 | M33: Major | N33: 22
A34: 110958 | B34: Walton County Sheriff's Office - GA | C34: 1420 | D34: 1351 | E34: 167 | F34: 250 | G34: 5 | H34: 206 | I34: T10 | J34: Full VR | K34: 45616 | L34: 45702 | M34: T1200 | N34: 9
A35: 105526 | B35: Baltimore City Police Dept - MD | C35: 1345 | D35: 436 | E35: 2530 | F35: 1200 | G35: 2836 | H35: 1240 | I35: T 7 | J35: Full VR | K35: 45273 | M35: Major | N35: 24
A36: 109160 | B36: North Carolina State Highway Patrol - NC | C36: 1320 | D36: 970 | E36: 1715 | F36: 1450 | G36: 120 | H36: 1585 | I36: T10 | J36: Full VR | K36: 45230 | M36: Major | N36: 33
A37: 106524 | B37: Weld County Sheriff's Office - CO | C37: 1297 | D37: 207 | E37: 82 | F37: 329 | G37: 335 | H37: 259 | I37: T10 | J37: Full VR | K37: 45637 | L37: 45728 | M37: Direct | N37: 9
A38: 107824 | B38: Jefferson County Sheriff's Office - CO | C38: 1273 | D38: 987 | E38: 667 | F38: 705 | G38: 565 | H38: 361 | I38: T10 | J38: Full VR | K38: 45642 | L38: 45742 | M38: Major | N38: 10
A39: 106338 | B39: Oregon State Police - OR | C39: 1269 | D39: 1269 | E39: 681 | F39: 750 | G39: 895 | H39: 775 | I39: T10 | J39: Full VR | K39: 45775 | L39: 45881 | M39: Major | N39: 4
A40: 111064 | B40: Lake County Sheriff's Office - FL | C40: 1264 | D40: 1017 | E40: 470 | F40: 933 | G40: 327 | H40: 453 | I40: T10 | J40: Full VR | K40: 45373 | M40: T1200 | N40: 18
...

Sheet Ceiling Agencies
A1: Account Number | B1: Account Name | C1: T12 SIM Usage | D1: T6 SIM Completions | E1: Active License Quantity | F1: Footprint Size | G1: Total T10 CEWs | H1: Time as Customer | I1: Threshold - Footprint | J1: Threshold - License | K1: Threshold - CEW | L1: 500+ Events | M1: 750+ Events | N1: 1000+ Events | O1: T6 500+ Events
A2: 114073 | B2: Texas Department of Public Safety - TX | C2: 2998 | D2: 2402 | E2: 2750 | F2: 1328 | G2: 3875 | H2: 12 | I2: 2.2575301 | J2: 1.0901818 | K2: 0.77367742 | L2: TRUE | M2: TRUE | N2: TRUE | O2: TRUE
A3: 105785 | B3: Fort Worth Police Department - TX | C3: 2323 | D3: 2003 | E3: 3861 | F3: 1993 | G3: 1904 | H3: 45 | I3: 1.1655795 | J3: 0.6016576 | K3: 1.220063 | L3: TRUE | M3: TRUE | N3: TRUE | O3: TRUE
A4: 175721 | B4: Boston Police Dept. - MA | C4: 1854 | D4: 861 | E4: 1570 | F4: 2200 | G4: 1622 | H4: 23 | I4: 0.84272727 | J4: 1.1808917 | K4: 1.1430333 | L4: TRUE | M4: TRUE | N4: TRUE | O4: TRUE
A5: 323664 | B5: Louisiana Department of Corrections - LA | C5: 1531 | D5: 1398 | E5: 1335 | F5: 1240 | G5: 973 | H5: 12 | I5: 1.2346774 | J5: 1.1468165 | K5: 1.5734841 | L5: TRUE | M5: TRUE | N5: TRUE | O5: TRUE
A6: 112474 | B6: Pinellas County Sheriff's Office - FL | C6: 1424 | D6: 895 | E6: 1110 | F6: 950 | G6: 1146 | H6: 22 | I6: 1.4989474 | J6: 1.2828829 | K6: 1.2425829 | L6: TRUE | M6: TRUE | N6: TRUE | O6: TRUE
A7: 109160 | B7: North Carolina State Highway Patrol - NC | C7: 1320 | D7: 970 | E7: 1450 | F7: 120 | G7: 1585 | H7: 33 | I7: 11 | J7: 0.91034483 | K7: 0.83280757 | L7: TRUE | M7: TRUE | N7: TRUE | O7: TRUE
