Workbook

Sheet Thi Sandbox
C3: 2025 Baseline
C4: Line Size | D4: Eligible Points | G4: % Mix | H4: APAP %
C5: Major | D5: 64815 | G5: =F5/$F$17 -> #DIV/0! | H5: =E5/F5 -> #DIV/0!
C6: T1200 | D6: 41166 | G6: =F6/$F$17 -> #DIV/0! | H6: =E6/F6 -> #DIV/0!
C7: Other | D7: 12075 | G7: =F7/$F$17 -> #DIV/0! | H7: =E7/F7 -> #DIV/0!
C8: Grand Total | D8: 118056 | G8: =F8/$F$17 -> #DIV/0! | H8: =E8/F8 -> #DIV/0!
G9: =F9/$F$17 -> #DIV/0! | H9: =E9/F9 -> #DIV/0!
G10: =F10/$F$17 -> #DIV/0! | H10: =E10/F10 -> #DIV/0!
G11: =F11/$F$17 -> #DIV/0! | H11: =E11/F11 -> #DIV/0!
G12: =F12/$F$17 -> #DIV/0! | H12: =E12/F12 -> #DIV/0!
G13: =F13/$F$17 -> #DIV/0! | H13: =E13/F13 -> #DIV/0!
G14: =F14/$F$17 -> #DIV/0! | H14: =E14/F14 -> #DIV/0!
G15: =F15/$F$17 -> #DIV/0! | H15: =E15/F15 -> #DIV/0!
G16: =F16/$F$17 -> #DIV/0! | H16: =E16/F16 -> #DIV/0!
G17: =F17/$F$17 -> #DIV/0! | H17: =E17/F17 -> #DIV/0!
C21: 2026 High Confidence | M21: 2026 High Confidence
C22: Row Labels | E22: Adopting Points | F22: Eligible Points | G22: % Mix | H22: APAP %
C23: 6 to 12 Months | E23: =SUM(E24:E26) -> #DIV/0! | F23: 40000 | G23: =F23/$F$35 -> 1 | H23: =E23/F23 -> #DIV/0! | M23: Retention Rate | O23: What % of adopting customers will still be adopting in 2026
C24: Major | E24: =F24*N32 -> #DIV/0! | F24: =$F$23*(F5/$F$8) -> #DIV/0! | G24: =F24/$F$35 -> #DIV/0! | H24: =E24/F24 -> #DIV/0! | M24: Major | N24: 0.7 | O24: Conservative estimate for high confidence
C25: T1200 | E25: =F25*N33 -> #DIV/0! | F25: =$F$23*(F6/$F$8) -> #DIV/0! | G25: =F25/$F$35 -> #DIV/0! | H25: =E25/F25 -> #DIV/0! | M25: T1200 | N25: 0.7
C26: Other | E26: =F26*N34 -> #DIV/0! | F26: =$F$23*(F7/$F$8) -> #DIV/0! | G26: =F26/$F$35 -> #DIV/0! | H26: =E26/F26 -> #DIV/0! | M26: Other | N26: 0.7
C27: 12 to 24 Months | E27: =SUM(E28:E30) -> 0 | F27: =F8 -> 0 | G27: =F27/$F$35 -> 0 | H27: =E27/F27 -> #DIV/0! | M27: Conversion Rate | O27: What % of unadopting customers will now adopt in 2026. Based on % of non-adopting customers that showed decent SIM activity on 2025 per cohort.
C28: Major | E28: =(E5*N24)+((F5-E5)*N28) -> 0 | F28: =F5 -> 0 | G28: =F28/$F$35 -> 0 | H28: =E28/F28 -> #DIV/0! | M28: Major | N28: 0.1 | O28: Based on % of non-adopting customers that showed decent SIM activity in 2025 across each line size.
C29: T1200 | E29: =(E6*N25)+((F6-E6)*N29) -> 0 | F29: =F6 -> 0 | G29: =F29/$F$35 -> 0 | H29: =E29/F29 -> #DIV/0! | M29: T1200 | N29: 0.25
C30: Other | E30: =(E7*N26)+((F7-E7)*N30) -> 0 | F30: =F7 -> 0 | G30: =F30/$F$35 -> 0 | H30: =E30/F30 -> #DIV/0! | M30: Other | N30: 0.3
C31: 24+ Months Total | E31: =SUM(E32:E34) -> 0 | F31: =F12+F16 -> 0 | G31: =F31/$F$35 -> 0 | H31: =E31/F31 -> #DIV/0! | M31: New Customer Adoption Rate | O31: What % of newly eligible customers will adopt in 2026 in less than 1 year's time.
C32: Major | E32: =((E9+E13)*N24)+(((F9-E9)+(F13-E13))*N28) -> 0 | F32: =F9+F13 -> 0 | G32: =F32/$F$35 -> 0 | H32: =E32/F32 -> #DIV/0! | M32: Major | N32: =H5*0.9 -> #DIV/0! | O32: =(N32-$H$5)*100 -> #DIV/0! | P32: ppts change YoY | R32: 10% Decrease from Nov'25 adoption rates to be conservative
C33: T1200 | E33: =((E10+E14)*N25)+(((F10-E10)+(F14-E14))*N29) -> 0 | F33: =F10+F14 -> 0 | G33: =F33/$F$35 -> 0 | H33: =E33/F33 -> #DIV/0! | M33: T1200 | N33: =H6*0.9 -> #DIV/0! | O33: =(N33-$H$6)*100 -> #DIV/0! | P33: ppts change YoY | R33: 10% Decrease from Nov'25 adoption rates to be conservative
C34: Other | E34: =((E11+E15)*N26)+(((F11-E11)+(F15-E15))*N30) -> 0 | F34: =F11+F15 -> 0 | G34: =F34/$F$35 -> 0 | H34: =E34/F34 -> #DIV/0! | M34: Other | N34: =H7*0.9 -> #DIV/0! | O34: =(N34-$H$7)*100 -> #DIV/0! | P34: ppts change YoY | R34: 10% Decrease from Nov'25 adoption rates to be conservative
C35: Grand Total | E35: =SUM(E31+E27+E23) -> #DIV/0! | F35: =F23+F27+F31 -> 40000 | G35: =F35/F35 -> 1 | H35: =E35/F35 -> #DIV/0!
C39: 2026 Hard Climb | M39: 2026 High Confidence
C40: Row Labels | E40: Adopting Points | F40: Eligible Points | G40: % Mix | H40: APAP %
C41: 6 to 12 Months | E41: =SUM(E42:E44) -> #DIV/0! | F41: 40000 | G41: =F41/$F$35 -> 1 | H41: =E41/F41 -> #DIV/0! | M41: Retention Rate | O41: What % of adopting customers will still be adopting in 2026
C42: Major | E42: =F42*N50 -> #DIV/0! | F42: =$F$41*(F5/$F$8) -> #DIV/0! | G42: =F42/$F$35 -> #DIV/0! | H42: =E42/F42 -> #DIV/0! | M42: Major | N42: 0.9 | O42: Assumes CSMs will be able to push customers to continue adopting. Still accounts for some drop offs (eg., recerts).
C43: T1200 | E43: =F43*N51 -> #DIV/0! | F43: =$F$41*(F6/$F$8) -> #DIV/0! | G43: =F43/$F$35 -> #DIV/0! | H43: =E43/F43 -> #DIV/0! | M43: T1200 | N43: 0.9
C44: Other | E44: =F44*N52 -> #DIV/0! | F44: =$F$41*(F7/$F$8) -> #DIV/0! | G44: =F44/$F$35 -> #DIV/0! | H44: =E44/F44 -> #DIV/0! | M44: Other | N44: 0.9
C45: 12 to 24 Months | E45: =SUM(E46:E48) -> 0 | F45: =F8 -> 0 | G45: =F45/$F$35 -> 0 | H45: =E45/F45 -> #DIV/0! | M45: Conversion Rate | O45: What % of unadopting customers will now adopt in 2026. Based on % of non-adopting customers that showed decent SIM activity on 2025 per cohort.
C46: Major | E46: =(E5*N42)+((F5-E5)*N46) -> 0 | F46: =F5 -> 0 | G46: =F46/$F$35 -> 0 | H46: =E46/F46 -> #DIV/0! | M46: Major | N46: 0.1 | O46: Assumes flat rate from High Confidence given engaging with lagging customers is both difficult and low priority for CSMs.
C47: T1200 | E47: =(E6*N43)+((F6-E6)*N47) -> 0 | F47: =F6 -> 0 | G47: =F47/$F$35 -> 0 | H47: =E47/F47 -> #DIV/0! | M47: T1200 | N47: 0.25
C48: Other | E48: =(E7*N44)+((F7-E7)*N48) -> 0 | F48: =F7 -> 0 | G48: =F48/$F$35 -> 0 | H48: =E48/F48 -> #DIV/0! | M48: Other | N48: 0.3
...

Sheet Goal Model (Final)
C2: 2025 Cohort | D2: 0-6 Months
C4: Line Size | D4: Sum of AgencySize | F4: 0.4 | G4: Growth in Eligible Points
C5: Major | D5: 3708
C6: Other | D6: 14691
C7: T1200 | D7: 14181
C8: Grand Total | D8: 32580
C10: 2026 Baseline
C11: 2025 Cohort | D11: Line Size | E11: Sum of No Qualifier Adopting Points | F11: Eligible Points | G11: % Mix | H11: APAP %
C12: 6-12 Months | D12: Major | E12: 16795 | F12: 37708 | G12: =F12/GETPIVOTDATA("Eligible Points",$C$11) -> 0.25549849 | H12: =E12/F12 -> 0.4453962
D13: T1200 | E13: 8016 | F13: 20937 | G13: =F13/GETPIVOTDATA("Eligible Points",$C$11) -> 0.14186305 | H13: =E13/F13 -> 0.38286287
D14: Other | E14: 5326 | F14: 8092 | G14: =F14/GETPIVOTDATA("Eligible Points",$C$11) -> 0.054829049 | H14: =E14/F14 -> 0.65818092
C15: 6-12 Months Total | E15: 30137 | F15: 66737 | G15: =F15/GETPIVOTDATA("Eligible Points",$C$11) -> 0.45219059 | H15: =E15/F15 -> 0.45157858
C16: 12-24 Months | D16: Major | E16: 4884 | F16: 19245 | G16: =F16/GETPIVOTDATA("Eligible Points",$C$11) -> 0.13039855 | H16: =E16/F16 -> 0.2537802
D17: T1200 | E17: 5668 | F17: 14130 | G17: =F17/GETPIVOTDATA("Eligible Points",$C$11) -> 0.095740788 | H17: =E17/F17 -> 0.40113234
D18: Other | E18: 1921 | F18: 3894 | G18: =F18/GETPIVOTDATA("Eligible Points",$C$11) -> 0.026384616 | H18: =E18/F18 -> 0.49332306
C19: 12-24 Months Total | E19: 12473 | F19: 37269 | G19: =F19/GETPIVOTDATA("Eligible Points",$C$11) -> 0.25252395 | H19: =E19/F19 -> 0.33467493
C20: 24+ Months | D20: Major | E20: 6204 | F20: 25493 | G20: =F20/GETPIVOTDATA("Eligible Points",$C$11) -> 0.17273319 | H20: =E20/F20 -> 0.24336092
D21: T1200 | E21: 4619 | F21: 15609 | G21: =F21/GETPIVOTDATA("Eligible Points",$C$11) -> 0.10576206 | H21: =E21/F21 -> 0.29591902
D22: Other | E22: 1297 | F22: 2478 | G22: =F22/GETPIVOTDATA("Eligible Points",$C$11) -> 0.01679021 | H22: =E22/F22 -> 0.52340597
C23: 24+ Months Total | E23: 12120 | F23: 43580 | G23: =F23/GETPIVOTDATA("Eligible Points",$C$11) -> 0.29528546 | H23: =E23/F23 -> 0.27810922
C24: Grand Total | E24: 54730 | F24: 147586 | G24: =F24/GETPIVOTDATA("Eligible Points",$C$11) -> 1 | H24: =E24/F24 -> 0.37083463
C28: 2026 High Confidence | M28: 2026 High Confidence
C29: Row Labels | E29: Adopting Points | F29: Eligible Points | G29: % Mix | H29: APAP %
C30: 6 to 12 Months (Forecasted) | E30: =SUM(E31:E33) -> 26585.135 | F30: =F24*F4 -> 59034.4 | G30: =F30/$F$46 -> 0.24679892 | H30: =E30/F30 -> 0.45033295 | M30: Retention Rate | O30: What % of adopting customers will still be adopting in 2026
C31: Major | E31: =F31*N43 -> 11674.546 | F31: =$F$30*(F12/$F$15) -> 33355.847 | G31: =F31/$F$46 -> 0.13944729 | H31: =E31/F31 -> 0.35 | M31: Major | N31: 0.8 | O31: Conservative estimate for high confidence
C32: T1200 | E32: =F32*N44 -> 10186.28 | F32: =$F$30*(F13/$F$15) -> 18520.509 | G32: =F32/$F$46 -> 0.077426749 | H32: =E32/F32 -> 0.55 | M32: T1200 | N32: 0.8
C33: Other | E33: =F33*N45 -> 4724.3089 | F33: =$F$30*(F14/$F$15) -> 7158.0437 | G33: =F33/$F$46 -> 0.029924882 | H33: =E33/F33 -> 0.66 | M33: Other | N33: 0.8
C34: 12 to 18 Months (Inelligible) | E34: =SUM(E35:E37) -> 14959.993 | F34: =D8 -> 32580 | G34: =F34/$F$46 -> 0.13620379 | H34: =E34/F34 -> 0.45917719 | M34: Conversion Rate | O34: What % of unadopting customers will now adopt in 2026. Based on % of non-adopting customers that showed decent SIM activity on 2025 per cohort.
C35: Major | E35: =(F35*N39*N31)+(F35-(F35*N39*N31))*N35 -> 6479.7845 | F35: =$F$34*(F12/$F$15) -> 18408.479 | G35: =F35/$F$46 -> 0.076958394 | H35: =E35/F35 -> 0.352 | M35: Major | N35: 0.1 | O35: Based on % of non-adopting customers that showed decent SIM activity in 2025 across each line size.
C36: T1200 | E36: =(F36*N40*N32)+(F36-(F36*N40*N32))*N36 -> 5928.2546 | F36: =$F$34*(F13/$F$15) -> 10221.129 | G36: =F36/$F$46 -> 0.042730399 | H36: =E36/F36 -> 0.58 | M36: T1200 | N36: 0.25
C37: Other | E37: =(F37*N41*N33)+(F37-(F37*N41*N33))*N37 -> 2551.9537 | F37: =$F$34*(F14/$F$15) -> 3950.3927 | G37: =F37/$F$46 -> 0.016514992 | H37: =E37/F37 -> 0.646 | M37: Other | N37: 0.25
C38: 18 to 24 Months (Current New) | E38: =SUM(E39:E41) -> 30122.65 | F38: =F15 -> 66737 | G38: =F38/$F$46 -> 0.27900037 | H38: =E38/F38 -> 0.45136356 | M38: Currently Ineligible Adoption Rate | O38: What % of currently ineligible customers will adopt in 2026 once eligible.
C39: Major | E39: =(E12*N31)+((F12-E12)*N35) -> 15527.3 | F39: =F12 -> 37708 | G39: =F39/$F$46 -> 0.15764188 | H39: =E39/F39 -> 0.41177734 | M39: Major | N39: 0.35 | O39: Assumes same initial adoption rates as 6-12 month cohort, then considers retention and conversion rates in model.
C40: T1200 | E40: =(E13*N32)+((F13-E13)*N36) -> 9643.05 | F40: =F13 -> 20937 | G40: =F40/$F$46 -> 0.087529118 | H40: =E40/F40 -> 0.46057458 | M40: T1200 | N40: 0.55
C41: Other | E41: =(E14*N33)+((F14-E14)*N37) -> 4952.3 | F41: =F14 -> 8092 | G41: =F41/$F$46 -> 0.033829375 | H41: =E41/F41 -> 0.61199951 | M41: Other | N41: 0.66
C42: 24+ Months Total (Pre 2025) | E42: =SUM(E43:E45) -> 28690.9 | F42: =F19+F23 -> 80849 | G42: =F42/$F$46 -> 0.33799693 | H42: =E42/F42 -> 0.35487019 | M42: New Customer Adoption Rate | O42: What % of newly eligible customers will adopt in 2026 in less than 1 year's time.
C43: Major | E43: =((E16+E20)*N31)+(((F16-E16)+(F20-E20))*N35) -> 12235.4 | F43: =F16+F20 -> 44738 | G43: =F43/$F$46 -> 0.18703146 | H43: =E43/F43 -> 0.2734901 | M43: Major | N43: 0.35 | O43: =(N43-H12)*100 -> -9.5396202 | P43: ppts change YoY | R43: 10% Decrease from Nov'25 rates to account for low adoption likelihood for Q2 majors
C44: T1200 | E44: =((E17+E21)*N32)+(((F17-E17)+(F21-E21))*N36) -> 13092.6 | F44: =F17+F21 -> 29739 | G44: =F44/$F$46 -> 0.12432672 | H44: =E44/F44 -> 0.44025018 | M44: T1200 | N44: 0.55 | O44: =(N44-H13)*100 -> 16.713713 | P44: ppts change YoY
C45: Other | E45: =((E18+E22)*N33)+(((F18-E18)+(F22-E22))*N37) -> 3362.9 | F45: =F18+F22 -> 6372 | G45: =F45/$F$46 -> 0.026638751 | H45: =E45/F45 -> 0.52776208 | M45: Other | N45: 0.66 | O45: =(N45-H14)*100 -> 0.18190806 | P45: ppts change YoY
C46: Grand Total | E46: =SUM(E42+E38+E30+E34) -> 100358.68 | F46: =F38+F42+F30+F34 -> 239200.4 | G46: =F46/F46 -> 1 | H46: =E46/F46 -> 0.41955899
...

Sheet Example Visualization Table
A2: Line Size | B2: High Confidence | C2: Hard Climb | D2: Actual | E2: Variance (pp)
A3: Retention Rate
A4: Major | B4: 0.8 | C4: 0.9
A5: T1200 | B5: 0.8 | C5: 0.9
A6: Other | B6: 0.8 | C6: 0.9
A7: Conversion Rate
A8: Major | B8: 0.1 | C8: 0.1
A9: T1200 | B9: 0.25 | C9: 0.25
A10: Other | B10: 0.25 | C10: 0.25
A11: Currently Ineligible Adoption Rate
A12: Major | B12: 0.35 | C12: 0.4
A13: T1200 | B13: 0.55 | C13: 0.6
A14: Other | B14: 0.66 | C14: 0.66
A15: New Customer Adoption Rate
A16: Major | B16: 0.35 | C16: 0.45
A17: T1200 | B17: 0.55 | C17: 0.5
A18: Other | B18: 0.66 | C18: 0.66
A24: Row Labels | B24: High Confidence | C24: Hard Climb | D24: Actual | E24: High Confidence Variance (pp) | F24: Hard Climb Variance (pp)
A25: 6 to 12 Months (Forecasted) | B25: 0.45033295 | C25: 0.49114914
A26: Major | B26: 0.35 | C26: 0.45
A27: T1200 | B27: 0.55 | C27: 0.5
A28: Other | B28: 0.66 | C28: 0.66
A29: 12 to 18 Months (Inelligible) | B29: 0.45917719 | C29: 0.52939019
A30: Major | B30: 0.352 | C30: 0.424
A31: T1200 | B31: 0.58 | C31: 0.655
A32: Other | B32: 0.646 | C32: 0.6955
A33: 18 to 24 Months (Current New) | B33: 0.45136356 | C33: 0.49652142
A34: Major | B34: 0.41177734 | C34: 0.45631696
A35: T1200 | B35: 0.46057458 | C35: 0.49886087
A36: Other | B36: 0.61199951 | C36: 0.6778176
... A41: Grand Total | B41: 0.41955899 | C41: 0.46207605

Sheet Goal Model (2)
C2: 2025 Cohort | D2: 0-6 Months | Q2: Just T6 0.75x | W2: T12 2x + T6 0.75x
Q3: Baseline | R3: 0.297 | W3: Baseline | X3: 0.362
C4: Line Size | D4: Sum of AgencySize | F4: 0.4 | G4: Growth in Eligible Points | Q4: HC | R4: 0.336 | W4: HC | X4: 0.377
C5: Major | D5: 3708 | Q5: Hard Climb | R5: 0.399 | W5: Hard Climb | X5: 0.454
C6: Other | D6: 14691
C7: T1200 | D7: 14181
C8: Grand Total | D8: 32580
C10: 2026 Baseline (w/ No T6 Qualifier) | O10: 2026 Baseline (w/ No T6 Qualifier) | W10: 2026 Baseline (w/ Majors T6 Qualifier)
C11: 2025 Cohort | D11: Line Size | E11: Sum of No Qualifier Adopting Points | F11: Eligible Points | G11: % Mix | H11: APAP % | O11: 2025 Cohort | P11: Line Size | Q11: Sum of T6 0.75x Only | R11: Eligible Points | S11: % Mix | T11: APAP % | W11: 2025 Cohort | X11: Line Size | Y11: Sum of Majors Qualifier Adopting Points | Z11: Eligible Points | AA11: % Mix | AB11: APAP %
C12: 6-12 Months | D12: Major | E12: 16795 | F12: 37708 | G12: =F12/$Z$24 -> 0.25549849 | H12: =E12/F12 -> 0.4453962 | O12: 6-12 Months | P12: Major | Q12: 14547 | R12: 37708 | S12: =R12/$Z$24 -> 0.25549849 | T12: =Q12/R12 -> 0.38578021 | W12: 6-12 Months | X12: Major | Y12: 16795 | Z12: 37708 | AA12: =Z12/$Z$24 -> 0.25549849 | AB12: =Y12/Z12 -> 0.4453962
D13: T1200 | E13: 8016 | F13: 20937 | G13: =F13/$Z$24 -> 0.14186305 | H13: =E13/F13 -> 0.38286287 | P13: T1200 | Q13: 5932 | R13: 20937 | S13: =R13/$Z$24 -> 0.14186305 | T13: =Q13/R13 -> 0.28332617 | X13: T1200 | Y13: 6490 | Z13: 20937 | AA13: =Z13/$Z$24 -> 0.14186305 | AB13: =Y13/Z13 -> 0.30997755
D14: Other | E14: 5326 | F14: 8092 | G14: =F14/$Z$24 -> 0.054829049 | H14: =E14/F14 -> 0.65818092 | P14: Other | Q14: 3214 | R14: 8092 | S14: =R14/$Z$24 -> 0.054829049 | T14: =Q14/R14 -> 0.3971824 | X14: Other | Y14: 4436 | Z14: 8092 | AA14: =Z14/$Z$24 -> 0.054829049 | AB14: =Y14/Z14 -> 0.54819575
C15: 6-12 Months Total | E15: 30137 | F15: 66737 | G15: =F15/$Z$24 -> 0.45219059 | H15: =E15/F15 -> 0.45157858 | O15: 6-12 Months Total | Q15: 23693 | R15: 66737 | S15: =R15/$Z$24 -> 0.45219059 | T15: =Q15/R15 -> 0.35502045 | W15: 6-12 Months Total | Y15: 27721 | Z15: 66737 | AA15: =Z15/$Z$24 -> 0.45219059 | AB15: =Y15/Z15 -> 0.41537678
C16: 12-24 Months | D16: Major | E16: 4884 | F16: 19245 | G16: =F16/$Z$24 -> 0.13039855 | H16: =E16/F16 -> 0.2537802 | O16: 12-24 Months | P16: Major | Q16: 4884 | R16: 19245 | S16: =R16/$Z$24 -> 0.13039855 | T16: =Q16/R16 -> 0.2537802 | W16: 12-24 Months | X16: Major | Y16: 4884 | Z16: 19245 | AA16: =Z16/$Z$24 -> 0.13039855 | AB16: =Y16/Z16 -> 0.2537802
D17: T1200 | E17: 5668 | F17: 14130 | G17: =F17/$Z$24 -> 0.095740788 | H17: =E17/F17 -> 0.40113234 | P17: T1200 | Q17: 4441 | R17: 14130 | S17: =R17/$Z$24 -> 0.095740788 | T17: =Q17/R17 -> 0.31429582 | X17: T1200 | Y17: 4024 | Z17: 14130 | AA17: =Z17/$Z$24 -> 0.095740788 | AB17: =Y17/Z17 -> 0.28478415
D18: Other | E18: 1921 | F18: 3894 | G18: =F18/$Z$24 -> 0.026384616 | H18: =E18/F18 -> 0.49332306 | P18: Other | Q18: 875 | R18: 3894 | S18: =R18/$Z$24 -> 0.026384616 | T18: =Q18/R18 -> 0.22470467 | X18: Other | Y18: 1789 | Z18: 3894 | AA18: =Z18/$Z$24 -> 0.026384616 | AB18: =Y18/Z18 -> 0.45942476
C19: 12-24 Months Total | E19: 12473 | F19: 37269 | G19: =F19/$Z$24 -> 0.25252395 | H19: =E19/F19 -> 0.33467493 | O19: 12-24 Months Total | Q19: 10200 | R19: 37269 | S19: =R19/$Z$24 -> 0.25252395 | T19: =Q19/R19 -> 0.27368591 | W19: 12-24 Months Total | Y19: 10697 | Z19: 37269 | AA19: =Z19/$Z$24 -> 0.25252395 | AB19: =Y19/Z19 -> 0.28702139
C20: 24+ Months | D20: Major | E20: 6204 | F20: 25493 | G20: =F20/$Z$24 -> 0.17273319 | H20: =E20/F20 -> 0.24336092 | O20: 24+ Months | P20: Major | Q20: 4467 | R20: 25493 | S20: =R20/$Z$24 -> 0.17273319 | T20: =Q20/R20 -> 0.17522457 | W20: 24+ Months | X20: Major | Y20: 6204 | Z20: 25493 | AA20: =Z20/$Z$24 -> 0.17273319 | AB20: =Y20/Z20 -> 0.24336092
D21: T1200 | E21: 4619 | F21: 15609 | G21: =F21/$Z$24 -> 0.10576206 | H21: =E21/F21 -> 0.29591902 | P21: T1200 | Q21: 3579 | R21: 15609 | S21: =R21/$Z$24 -> 0.10576206 | T21: =Q21/R21 -> 0.22929079 | X21: T1200 | Y21: 3073 | Z21: 15609 | AA21: =Z21/$Z$24 -> 0.10576206 | AB21: =Y21/Z21 -> 0.1968736
D22: Other | E22: 1297 | F22: 2478 | G22: =F22/$Z$24 -> 0.01679021 | H22: =E22/F22 -> 0.52340597 | P22: Other | Q22: 1179 | R22: 2478 | S22: =R22/$Z$24 -> 0.01679021 | T22: =Q22/R22 -> 0.47578692 | X22: Other | Y22: 788 | Z22: 2478 | AA22: =Z22/$Z$24 -> 0.01679021 | AB22: =Y22/Z22 -> 0.31799839
C23: 24+ Months Total | E23: 12120 | F23: 43580 | G23: =F23/$Z$24 -> 0.29528546 | H23: =E23/F23 -> 0.27810922 | O23: 24+ Months Total | Q23: 9225 | R23: 43580 | S23: =R23/$Z$24 -> 0.29528546 | T23: =Q23/R23 -> 0.21167967 | W23: 24+ Months Total | Y23: 10065 | Z23: 43580 | AA23: =Z23/$Z$24 -> 0.29528546 | AB23: =Y23/Z23 -> 0.23095457
C24: Grand Total | E24: 54730 | F24: 147586 | G24: =F24/$Z$24 -> 1 | H24: =E24/F24 -> 0.37083463 | O24: Grand Total | Q24: 43118 | R24: 147586 | S24: =R24/$Z$24 -> 1 | T24: =Q24/R24 -> 0.29215508 | W24: Grand Total | Y24: 48483 | Z24: 147586 | AA24: =Z24/$Z$24 -> 1 | AB24: =Y24/Z24 -> 0.32850677
C28: 2026 High Confidence | M28: 2026 High Confidence
C29: Row Labels | E29: Adopting Points | F29: Eligible Points | G29: % Mix | H29: APAP %
C30: 6 to 12 Months (Forecasted) | E30: =SUM(E31:E33) -> 20759.415 | F30: =F24*F4 -> 59034.4 | G30: =F30/$F$46 -> 0.24679892 | H30: =E30/F30 -> 0.35164946 | M30: Retention Rate | O30: What % of adopting customers will still be adopting in 2026
C31: Major | E31: =F31*N43 -> 10340.313 | F31: =$F$30*(F12/$F$15) -> 33355.847 | G31: =F31/$F$46 -> 0.13944729 | H31: =E31/F31 -> 0.31 | M31: Major | N31: 0.75 | O31: Conservative estimate for high confidence
C32: T1200 | E32: =F32*N44 -> 6482.1783 | F32: =$F$30*(F13/$F$15) -> 18520.509 | G32: =F32/$F$46 -> 0.077426749 | H32: =E32/F32 -> 0.35 | M32: T1200 | N32: 0.75
C33: Other | E33: =F33*N45 -> 3936.9241 | F33: =$F$30*(F14/$F$15) -> 7158.0437 | G33: =F33/$F$46 -> 0.029924882 | H33: =E33/F33 -> 0.55 | M33: Other | N33: 0.75
C34: 12 to 18 Months (Inelligible) | E34: =SUM(E35:E37) -> 14681.882 | F34: =D8 -> 32580 | G34: =F34/$F$46 -> 0.13620379 | H34: =E34/F34 -> 0.45064095 | M34: Conversion Rate | O34: What % of unadopting customers will now adopt in 2026. Based on % of non-adopting customers that showed decent SIM activity on 2025 per cohort.
C35: Major | E35: =(F35*N39*N31)+(F35-(F35*N39*N31))*N35 -> 7375.2177 | F35: =$F$34*(F12/$F$15) -> 18408.479 | G35: =F35/$F$46 -> 0.076958394 | H35: =E35/F35 -> 0.40064244 | M35: Major | N35: 0.1 | O35: Based on % of non-adopting customers that showed decent SIM activity in 2025 across each line size.
C36: T1200 | E36: =(F36*N40*N32)+(F36-(F36*N40*N32))*N36 -> 4756.5082 | F36: =$F$34*(F13/$F$15) -> 10221.129 | G36: =F36/$F$46 -> 0.042730399 | H36: =E36/F36 -> 0.46536037 | M36: T1200 | N36: 0.25
C37: Other | E37: =(F37*N41*N33)+(F37-(F37*N41*N33))*N37 -> 2550.1562 | F37: =$F$34*(F14/$F$15) -> 3950.3927 | G37: =F37/$F$46 -> 0.016514992 | H37: =E37/F37 -> 0.64554498 | M37: Other | N37: 0.3
C38: 18 to 24 Months (Current New) | E38: =SUM(E39:E41) -> 28754.1 | F38: =F15 -> 66737 | G38: =F38/$F$46 -> 0.27900037 | H38: =E38/F38 -> 0.43085695 | M38: Currently Ineligible Adoption Rate | O38: What % of currently ineligible customers will adopt in 2026 once eligible.
C39: Major | E39: =(E12*N31)+((F12-E12)*N35) -> 14687.55 | F39: =F12 -> 37708 | G39: =F39/$F$46 -> 0.15764188 | H39: =E39/F39 -> 0.38950753 | M39: Major | N39: =H12 -> 0.4453962 | O39: Assumes same initial adoption rates as 6-12 month cohort, then considers retention and conversion rates in model.
C40: T1200 | E40: =(E13*N32)+((F13-E13)*N36) -> 9242.25 | F40: =F13 -> 20937 | G40: =F40/$F$46 -> 0.087529118 | H40: =E40/F40 -> 0.44143144 | M40: T1200 | N40: =H13 -> 0.38286287
C41: Other | E41: =(E14*N33)+((F14-E14)*N37) -> 4824.3 | F41: =F14 -> 8092 | G41: =F41/$F$46 -> 0.033829375 | H41: =E41/F41 -> 0.59618141 | M41: Other | N41: =H14 -> 0.65818092
C42: 24+ Months Total (Pre 2025) | E42: =SUM(E43:E45) -> 27618.95 | F42: =F19+F23 -> 80849 | G42: =F42/$F$46 -> 0.33799693 | H42: =E42/F42 -> 0.34161152 | M42: New Customer Adoption Rate | O42: What % of newly eligible customers will adopt in 2026 in less than 1 year's time.
C43: Major | E43: =((E16+E20)*N31)+(((F16-E16)+(F20-E20))*N35) -> 11681 | F43: =F16+F20 -> 44738 | G43: =F43/$F$46 -> 0.18703146 | H43: =E43/F43 -> 0.26109795 | M43: Major | N43: 0.31 | O43: =(N43-AB12)*100 -> -13.53962 | P43: ppts change YoY | R43: 10% Decrease from Nov'25 rates to account for low adoption likelihood for Q2 majors
C44: T1200 | E44: =((E17+E21)*N32)+(((F17-E17)+(F21-E21))*N36) -> 12578.25 | F44: =F17+F21 -> 29739 | G44: =F44/$F$46 -> 0.12432672 | H44: =E44/F44 -> 0.42295471 | M44: T1200 | N44: 0.35 | O44: =(N44-AB13)*100 -> 4.0022448 | P44: ppts change YoY
C45: Other | E45: =((E18+E22)*N33)+(((F18-E18)+(F22-E22))*N37) -> 3359.7 | F45: =F18+F22 -> 6372 | G45: =F45/$F$46 -> 0.026638751 | H45: =E45/F45 -> 0.52725989 | M45: Other | N45: 0.55 | O45: =(N45-AB14)*100 -> 0.18042511 | P45: ppts change YoY
...

Sheet Engagement M&M Data
A1: AgencyName | B1: AgencySlug | C1: AgencySize | D1: VR_Licenses | E1: Eligibility_Cohort | F1: Sept_Completions | G1: Oct_Completions | H1: Nov_Completions
A2: Baltimore County Police Dept. - MD | B2: 114601 | C2: 2194 | D2: 1703 | E2: 10 | F2: 1829 | G2: 0 | H2: 0
A3: Albuquerque Police Dept. - NM | B3: 116660 | C3: 1335 | D3: 1300 | E3: 10 | F3: 160 | G3: 56 | H3: 131
A4: San Bernardino County Probation Dept. - CA | B4: 302836 | C4: 8 | D4: 505 | E4: 7 | F4: 487 | G4: 198 | H4: 65
A5: Maryland State Police - MD | B5: 108541 | C5: 2325 | D5: 750 | E5: 11 | F5: 142 | G5: 162 | H5: 1
A6: Bakersfield Police Dept. - CA | B6: 127250 | C6: 625 | D6: 470 | E6: 10 | F6: 110 | G6: 82 | H6: 75
A7: Seminole County Sheriff's Office - FL | B7: 107092 | C7: 570 | D7: 790 | E7: 38 | F7: 62 | G7: 25 | H7: 0
A8: Oklahoma City Police Dept. - OK | B8: 113118 | C8: 1458 | D8: 700 | E8: 49 | F8: 0 | G8: 7 | H8: 11
A9: Charlotte County Sheriff's Office - FL | B9: 108467 | C9: 230 | D9: 488 | E9: 6 | F9: 597 | G9: 1007 | H9: 634
A10: Hamilton County Sheriff's Office - OH | B10: 106522 | C10: 690 | D10: 626 | E10: 7 | F10: 517 | G10: 93 | H10: 2
A11: Texas Department of Public Safety - TX | B11: 114073 | C11: 1328 | D11: 2750 | E11: 12 | F11: 333 | G11: 1741 | H11: 365
A12: Minneapolis Police Dept. - MN | B12: 106372 | C12: 650 | D12: 600 | E12: 9 | F12: 6 | G12: 31 | H12: 99
A13: Fort Worth Police Department - TX | B13: 105785 | C13: 1993 | D13: 3486 | E13: 45 | F13: 3107 | G13: 260 | H13: 6
... A67: Scranton Police Dept. - PA | B67: 305896 | C67: 152 | D67: 130 | E67: 8 | F67: 76 | G67: 251 | H67: 0
A68: Barrie Police Service | B68: CA0115465 | C68: 322 | D68: 155 | E68: 17 | F68: 10 | G68: 0 | H68: 20
A69: Burbank Police Dept. - CA | B69: 155263 | C69: 154 | D69: 178 | E69: 14 | F69: 270 | G69: 0 | H69: 9
A70: Bloomington Police Dept. - MN | B70: 157071 | C70: 151 | D70: 140 | E70: 34 | F70: 0 | G70: 27 | H70: 0
A71: National Commissioner of the Icelandic Police | B71: 532247 | C71: 703 | D71: 480 | E71: 24 | F71: 204 | G71: 142 | H71: 0
A72: Tampa Police Department - FL | B72: 105702 | C72: 928 | D72: 1000 | E72: 11 | F72: 1 | G72: 3 | H72: 95
A73: Virginia Beach Police Dept. - VA | B73: 112305 | C73: 888 | D73: 508 | E73: 52 | F73: 12 | G73: 0 | H73: 0
A74: Leon County Sheriff's Dept. - FL | B74: 112129 | C74: 538 | D74: 473 | E74: 25 | F74: 44 | G74: 290 | H74: 0
A75: Richardson Police Department - TX | B75: 451087 | C75: 191 | D75: 180 | E75: 11 | F75: 133 | G75: 88 | H75: 70
A76: Boston Police Dept. - MA | B76: 175721 | C76: 2200 | D76: 1570 | E76: 23 | F76: 266 | G76: 27 | H76: 117
A77: Lower Merion Twp Police Dept. - PA | B77: 107969 | C77: 7 | D77: 136 | E77: 9 | F77: 15 | G77: 0 | H77: 0
A78: Wilson Police Department - NC | B78: 110526 | C78: 119 | D78: 125 | E78: 10 | F78: 10 | G78: 6 | H78: 4
A79: Arizona Department of Corrections - AZ | B79: 107741 | C79: 1651 | D79: 1466 | E79: 6 | F79: 143 | G79: 28 | H79: 346
A80: Peel Regional Police Service - CAN | B80: CA0115409 | C80: 2119 | D80: 750 | E80: 7 | F80: 125 | G80: 56 | H80: 27
A81: Will County Sheriff Office Enforcement - IL | B81: 511036 | C81: 231 | D81: 240 | E81: 21 | F81: 43 | G81: 0 | H81: 0
A82: Port of Seattle Police Dept. - WA | B82: 106528 | C82: 120 | D82: 150 | E82: 7 | F82: 2 | G82: 430 | H82: 24
A83: Walker Police Dept. - MI | B83: 179811 | C83: 48 | D83: 43 | E83: 13 | F83: 0 | G83: 6 | H83: 16
A84: Springfield Police Department - IL | B84: 109079 | C84: 280 | D84: 274 | E84: 34 | F84: 1 | G84: 0 | H84: 0
A85: Centralia Police Dept. - IL | B85: 155646 | C85: 29 | D85: 26 | E85: 9 | F85: 0 | G85: 33 | H85: 7
A86: San Leandro Police Dept. - CA | B86: 108570 | C86: 115 | D86: 100 | E86: 13 | F86: 8 | G86: 4 | H86: 5
A87: Hemet Police Department - CA | B87: 149220 | C87: 0 | D87: 100 | E87: 7 | F87: 8 | G87: 8 | H87: 61
A88: Hemet Police Department - CA | B88: 149220 | C88: 103 | D88: 100 | E88: 7 | F88: 8 | G88: 8 | H88: 61
A89: Metropolitan Transit Authority of Harris County - TX | B89: 107794 | C89: 250 | D89: 274 | E89: 25 | F89: 51 | G89: 42 | H89: 0
A90: North Carolina State Highway Patrol - NC | B90: 109160 | C90: 120 | D90: 1450 | E90: 34 | F90: 3 | G90: 69 | H90: 0
A91: Wauwatosa Police Dept. - WI | B91: 112209 | C91: 123 | D91: 75 | E91: 9 | F91: 0 | G91: 0 | H91: 0
A92: Spokane Police Dept. - WA | B92: 446518 | C92: 344 | D92: 343 | E92: 40 | F92: 96 | G92: 348 | H92: 20
... A201: University of Rochester | B201: 551353 | C201: 85 | D201: 85 | E201: 12 | F201: 46 | G201: 0 | H201: 1
...

Sheet Engagement M&M Baselines
B2: Month | C2: Metric | D2: Value
B3: September | C3: Agency Count | D3: 514
C4: VR Licenses | D4: 127003
C5: SIM Completions | D5: 16064
C6: % Agencies Engaged | D6: 0.407
C7: Completions per License | D7: 0.13
C8: Completions per Agency | D8: 31.25
B9: October | C9: Agency Count | D9: 550
C10: VR Licenses | D10: 134378
C11: SIM Completions | D11: 16022
C12: % Agencies Engaged | D12: 0.424
C13: Completions per License | D13: 0.12
C14: Completions per Agency | D14: 29.13
B15: November | C15: Agency Count | D15: 613
C16: VR Licenses | D16: 141800 | G16: Sum of T3 months / licenses
C17: SIM Completions | D17: 12240 | G17: T12 SIM completions / licenses (in mo 12)
C18: % Agencies Engaged | D18: 0.392 | G18: 60% growth in T12 SIM adoption YoY across all SIM customers, from 250k to 400k by 11/30/2026
C19: Completions per License | D19: 0.09
C20: Completions per Agency | D20: 19.97
B21: 90 Day Average | C21: % Agencies Engaged | D21: 0.407
C22: Completions per License | D22: =AVERAGE(D7,D13,D19) -> 0.11333333
C23: Completions per Agency | D23: 26.78
C24: T12 Completions per License

Sheet Baseline Analysis
A1: Threshold | B1: APAP% | C1: Agency Count | D1: Adopting Points | F1: Eligible Points
A2: T12 1.5x | B2: =D2/$F$2 -> 0.28955999 | C2: =COUNTIFS('v2 Data'!I:I, ">=1.5",'v2 Data'!E:E, ">=6") -> 259 | D2: =SUMIFS('v2 Data'!C:C, 'v2 Data'!I:I,">=1.5", 'v2 Data'!E:E, ">=6") -> 42735 | F2: ='Goal Model (2)'!Z24 -> 147586
A3: T12 2x | B3: =D3/$F$2 -> 0.21686339 | C3: =COUNTIFS('v2 Data'!I:I, ">=2",'v2 Data'!E:E, ">=6") -> 217 | D3: =SUMIFS('v2 Data'!C:C, 'v2 Data'!I:I,">=2", 'v2 Data'!E:E, ">=6") -> 32006
A4: T12 2x OR T3 300 | B4: =D4/$F$2 -> #N/A | C4: {=SUMPRODUCT(--(('v2 Data'!I2:I611>=2) + ('v2 Data'!H2:H611>=300) > 0))} -> 169 | D4: {=SUMPRODUCT((('v2 Data'!I2:I1400>=2) * ('v2 Data'!E2:E1400>=6) * 'v2 Data'!C2:C611))} -> #N/A
A5: T12 2x OR T6 500 | B5: =D5/$F$2 -> 0.28150367 | C5: {=SUMPRODUCT(--(('v2 Data'!I2:I611>=2) + ('v2 Data'!G2:G611>=500) > 0))} -> 170 | D5: {=SUMPRODUCT((('v2 Data'!I2:I611>=2) + ('v2 Data'!G2:G611>=500) > 0) * 'v2 Data'!C2:C611)} -> 41546
A6: T12 2x OR T12 1000 | B6: =D6/$F$2 -> 0.29323242 | C6: {=SUMPRODUCT(--(('v2 Data'!I4:I613>=2) + ('v2 Data'!F4:F613>=1000) > 0))} -> 172 | D6: {=SUMPRODUCT((('v2 Data'!I2:I611>=2) + ('v2 Data'!F2:F611>=1000) > 0) * 'v2 Data'!C2:C611)} -> 43277
A7: T12 2x OR T3 0.75x for 550+ Agencies | B7: =D7/$F$2 -> 0.22493326 | C7: =COUNTIF('v2 Data'!I2:I611, ">=2") + COUNTIFS('v2 Data'!D2:D611,">=500",'v2 Data'!K2:K611,">=0.75", 'v2 Data'!I2:I611, "<2") -> 163 | D7: {=SUMPRODUCT(('v2 Data'!I2:I611>=2) * 'v2 Data'!C2:C611 + (('v2 Data'!D2:D611>=500) * ('v2 Data'!K2:K611>=0.75) * ('v2 Data'!I2:I611<2) * 'v2 Data'!C2:C611))} -> 33197
A8: T12 2x OR T6 0.75x | B8: =D8/$F$2 -> 0.37083463 | C8: =COUNTIFS(Data!I:I, ">=2", Data!E:E, ">=6") + COUNTIFS(Data!J:J,">=0.75", Data!I:I, "<2", Data!E:E, ">=6") -> 284 | D8: {=SUMPRODUCT(--(Data!I2:I1282>=2) * --(Data!E2:E1282>=6) * Data!C2:C1282 + --(Data!I2:I1282<2) * --(Data!J2:J1282>=0.75) * --(Data!E2:E1282>=6) * Data!C2:C1282)} -> 54730
A9: T12 2x OR T12 1x for 550+ Agencies | B9: =D9/$F$2 -> 0.26541135 | C9: =COUNTIF('v2 Data'!I2:I611, ">=2") + COUNTIFS('v2 Data'!D2:D611,">=500",'v2 Data'!I2:I611,">=1", 'v2 Data'!I2:I611, "<2") -> 171 | D9: {=SUMPRODUCT(('v2 Data'!I2:I611>=2) * 'v2 Data'!C2:C611 + (('v2 Data'!D2:D611>=500) * ('v2 Data'!I2:I611>=1) * ('v2 Data'!I2:I611<2) * 'v2 Data'!C2:C611))} -> 39171

Sheet Data
A1: AgencySlug | B1: AgencyName | C1: AgencySize | D1: VR_Licenses | E1: Eligibility_Cohort | F1: T12_SIM_Completions | G1: T6_SIM_Completions | H1: T3_SIM_Completions | I1: T12_SIM_Per_Person | J1: T6_SIM_Per_Person | K1: T3_SIM_Per_Person | L1: T6_Non_SIM_Completions | M1: 2025 Cohort | N1: 2026 Cohort | O1: Line Size | P1: No Qualifier Adopting Points | Q1: Majors Qualifier Adopting Points | R1: T6 0.75x Only
A2: 111124 | B2: Leander Police Dept. - TX | C2: 88 | D2: 87 | E2: 60 | F2: 558 | G2: 468 | H2: 221 | I2: 6.41 | J2: 5.38 | K2: 2.54 | L2: 5 | M2: =IF(E2<6,"0-6 Months", IF(E2<13, "6-12 Months", IF(E2<19, "12-24 Months", IF(E2<25, "12-24 Months", "24+ Months")))) -> 24+ Months | N2: =IF(E2<6,"12-18 Months", IF(E2<13, "18-24 Months", "24+ Months")) -> 24+ Months | O2: Other | P2: =IF(I2>=2, C2, IF(J2>=0.75, C2, 0)) -> 88 | Q2: =IF(I2>=2, C2, IF(AND(J2>=0.75, D2>=550), C2, 0)) -> 88 | R2: =IF(J2>=0.75, C2, 0) -> 88
A3: 112305 | B3: Virginia Beach Police Dept. - VA | C3: 888 | D3: 508 | E3: 52 | F3: 647 | G3: 65 | H3: 12 | I3: 1.27 | J3: 0.13 | K3: 0.02 | L3: 36 | M3: =IF(E3<6,"0-6 Months", IF(E3<13, "6-12 Months", IF(E3<19, "12-24 Months", IF(E3<25, "12-24 Months", "24+ Months")))) -> 24+ Months | N3: =IF(E3<6,"12-18 Months", IF(E3<13, "18-24 Months", "24+ Months")) -> 24+ Months | O3: T1200 | P3: =IF(I3>=2, C3, IF(J3>=0.75, C3, 0)) -> 0 | Q3: =IF(I3>=2, C3, IF(AND(J3>=0.75, D3>=550), C3, 0)) -> 0 | R3: =IF(J3>=0.75, C3, 0) -> 0
A4: 110456 | B4: Brighton Police Department - CO | C4: 78 | D4: 91 | E4: 51 | F4: 0 | G4: 0 | H4: 0 | I4: 0 | J4: 0 | K4: 0 | L4: 0 | M4: =IF(E4<6,"0-6 Months", IF(E4<13, "6-12 Months", IF(E4<19, "12-24 Months", IF(E4<25, "12-24 Months", "24+ Months")))) -> 24+ Months | N4: =IF(E4<6,"12-18 Months", IF(E4<13, "18-24 Months", "24+ Months")) -> 24+ Months | O4: Other | P4: =IF(I4>=2, C4, IF(J4>=0.75, C4, 0)) -> 0 | Q4: =IF(I4>=2, C4, IF(AND(J4>=0.75, D4>=550), C4, 0)) -> 0 | R4: =IF(J4>=0.75, C4, 0) -> 0
A5: 124615 | B5: Auburn Police Dept - AL | C5: 148 | D5: 120 | E5: 51 | F5: 1656 | G5: 1209 | H5: 710 | I5: 13.8 | J5: 10.08 | K5: 5.92 | L5: 8 | M5: =IF(E5<6,"0-6 Months", IF(E5<13, "6-12 Months", IF(E5<19, "12-24 Months", IF(E5<25, "12-24 Months", "24+ Months")))) -> 24+ Months | N5: =IF(E5<6,"12-18 Months", IF(E5<13, "18-24 Months", "24+ Months")) -> 24+ Months | O5: T1200 | P5: =IF(I5>=2, C5, IF(J5>=0.75, C5, 0)) -> 148 | Q5: =IF(I5>=2, C5, IF(AND(J5>=0.75, D5>=550), C5, 0)) -> 148 | R5: =IF(J5>=0.75, C5, 0) -> 148
A6: 110104 | B6: Lake Hamilton Police Dept.- FL | C6: 1 | D6: 12 | E6: 50 | F6: 22 | G6: 0 | H6: 0 | I6: 1.83 | J6: 0 | K6: 0 | L6: 0 | M6: =IF(E6<6,"0-6 Months", IF(E6<13, "6-12 Months", IF(E6<19, "12-24 Months", IF(E6<25, "12-24 Months", "24+ Months")))) -> 24+ Months | N6: =IF(E6<6,"12-18 Months", IF(E6<13, "18-24 Months", "24+ Months")) -> 24+ Months | O6: Other | P6: =IF(I6>=2, C6, IF(J6>=0.75, C6, 0)) -> 0 | Q6: =IF(I6>=2, C6, IF(AND(J6>=0.75, D6>=550), C6, 0)) -> 0 | R6: =IF(J6>=0.75, C6, 0) -> 0
A7: 128243 | B7: Winnfield Police Dept. - LA | C7: 1 | D7: 20 | E7: 50 | F7: 0 | G7: 0 | H7: 0 | I7: 0 | J7: 0 | K7: 0 | L7: 0 | M7: =IF(E7<6,"0-6 Months", IF(E7<13, "6-12 Months", IF(E7<19, "12-24 Months", IF(E7<25, "12-24 Months", "24+ Months")))) -> 24+ Months | N7: =IF(E7<6,"12-18 Months", IF(E7<13, "18-24 Months", "24+ Months")) -> 24+ Months | O7: Other | P7: =IF(I7>=2, C7, IF(J7>=0.75, C7, 0)) -> 0 | Q7: =IF(I7>=2, C7, IF(AND(J7>=0.75, D7>=550), C7, 0)) -> 0 | R7: =IF(J7>=0.75, C7, 0) -> 0
A8: 302987 | B8: Brush Police Department - CO | C8: 16 | D8: 28 | E8: 50 | F8: 8 | G8: 1 | H8: 0 | I8: 0.29 | J8: 0.04 | K8: 0 | L8: 0 | M8: =IF(E8<6,"0-6 Months", IF(E8<13, "6-12 Months", IF(E8<19, "12-24 Months", IF(E8<25, "12-24 Months", "24+ Months")))) -> 24+ Months | N8: =IF(E8<6,"12-18 Months", IF(E8<13, "18-24 Months", "24+ Months")) -> 24+ Months | O8: Other | P8: =IF(I8>=2, C8, IF(J8>=0.75, C8, 0)) -> 0 | Q8: =IF(I8>=2, C8, IF(AND(J8>=0.75, D8>=550), C8, 0)) -> 0 | R8: =IF(J8>=0.75, C8, 0) -> 0
A9: 206457 | B9: Hillsboro Beach Police Dept.-FL | C9: 18 | D9: 20 | E9: 50 | F9: 1 | G9: 1 | H9: 0 | I9: 0.05 | J9: 0.05 | K9: 0 | L9: 0 | M9: =IF(E9<6,"0-6 Months", IF(E9<13, "6-12 Months", IF(E9<19, "12-24 Months", IF(E9<25, "12-24 Months", "24+ Months")))) -> 24+ Months | N9: =IF(E9<6,"12-18 Months", IF(E9<13, "18-24 Months", "24+ Months")) -> 24+ Months | O9: Other | P9: =IF(I9>=2, C9, IF(J9>=0.75, C9, 0)) -> 0 | Q9: =IF(I9>=2, C9, IF(AND(J9>=0.75, D9>=550), C9, 0)) -> 0 | R9: =IF(J9>=0.75, C9, 0) -> 0
A10: 107396 | B10: Bradley County Sheriff's Office - TN | C10: 106 | D10: 130 | E10: 50 | F10: 25 | G10: 25 | H10: 25 | I10: 0.19 | J10: 0.19 | K10: 0.19 | L10: 35 | M10: =IF(E10<6,"0-6 Months", IF(E10<13, "6-12 Months", IF(E10<19, "12-24 Months", IF(E10<25, "12-24 Months", "24+ Months")))) -> 24+ Months | N10: =IF(E10<6,"12-18 Months", IF(E10<13, "18-24 Months", "24+ Months")) -> 24+ Months | O10: T1200 | P10: =IF(I10>=2, C10, IF(J10>=0.75, C10, 0)) -> 0 | Q10: =IF(I10>=2, C10, IF(AND(J10>=0.75, D10>=550), C10, 0)) -> 0 | R10: =IF(J10>=0.75, C10, 0) -> 0
A11: 109997 | B11: Middletown Police Dept. - CT | C11: 119 | D11: 125 | E11: 50 | F11: 29 | G11: 28 | H11: 24 | I11: 0.23 | J11: 0.22 | K11: 0.19 | L11: 27 | M11: =IF(E11<6,"0-6 Months", IF(E11<13, "6-12 Months", IF(E11<19, "12-24 Months", IF(E11<25, "12-24 Months", "24+ Months")))) -> 24+ Months | N11: =IF(E11<6,"12-18 Months", IF(E11<13, "18-24 Months", "24+ Months")) -> 24+ Months | O11: T1200 | P11: =IF(I11>=2, C11, IF(J11>=0.75, C11, 0)) -> 0 | Q11: =IF(I11>=2, C11, IF(AND(J11>=0.75, D11>=550), C11, 0)) -> 0 | R11: =IF(J11>=0.75, C11, 0) -> 0
A12: 111152 | B12: Federal Way Police Dept. - WA | C12: 130 | D12: 150 | E12: 50 | F12: 0 | G12: 0 | H12: 0 | I12: 0 | J12: 0 | K12: 0 | L12: 3 | M12: =IF(E12<6,"0-6 Months", IF(E12<13, "6-12 Months", IF(E12<19, "12-24 Months", IF(E12<25, "12-24 Months", "24+ Months")))) -> 24+ Months | N12: =IF(E12<6,"12-18 Months", IF(E12<13, "18-24 Months", "24+ Months")) -> 24+ Months | O12: T1200 | P12: =IF(I12>=2, C12, IF(J12>=0.75, C12, 0)) -> 0 | Q12: =IF(I12>=2, C12, IF(AND(J12>=0.75, D12>=550), C12, 0)) -> 0 | R12: =IF(J12>=0.75, C12, 0) -> 0
A13: 109207 | B13: Kissimmee Police Dept. - FL | C13: 162 | D13: 166 | E13: 50 | F13: 313 | G13: 227 | H13: 143 | I13: 1.89 | J13: 1.37 | K13: 0.86 | L13: 139 | M13: =IF(E13<6,"0-6 Months", IF(E13<13, "6-12 Months", IF(E13<19, "12-24 Months", IF(E13<25, "12-24 Months", "24+ Months")))) -> 24+ Months | N13: =IF(E13<6,"12-18 Months", IF(E13<13, "18-24 Months", "24+ Months")) -> 24+ Months | O13: T1200 | P13: =IF(I13>=2, C13, IF(J13>=0.75, C13, 0)) -> 162 | Q13: =IF(I13>=2, C13, IF(AND(J13>=0.75, D13>=550), C13, 0)) -> 0 | R13: =IF(J13>=0.75, C13, 0) -> 162
... A112: 106000 | B112: Atlanta Police Dept. - GA | C112: 2337 | D112: 2337 | E112: 33 | F112: 277 | G112: 164 | H112: 134 | I112: 0.12 | J112: 0.07 | K112: 0.06 | L112: 0 | M112: =IF(E112<6,"0-6 Months", IF(E112<13, "6-12 Months", IF(E112<19, "12-24 Months", IF(E112<25, "12-24 Months", "24+ Months")))) -> 24+ Months | N112: =IF(E112<6,"12-18 Months", IF(E112<13, "18-24 Months", "24+ Months")) -> 24+ Months | O112: Major | P112: =IF(I112>=2, C112, IF(J112>=0.75, C112, 0)) -> 0 | Q112: =IF(I112>=2, C112, IF(AND(J112>=0.75, D112>=550), C112, 0)) -> 0 | R112: =IF(J112>=0.75, C112, 0) -> 0
A113: CA0115604 | B113: Manitoba First Nations Police Service | C113: 1 | D113: 57 | E113: 31 | F113: 155 | G113: 67 | H113: 0 | I113: 2.72 | J113: 1.18 | K113: 0 | L113: 24 | M113: =IF(E113<6,"0-6 Months", IF(E113<13, "6-12 Months", IF(E113<19, "12-24 Months", IF(E113<25, "12-24 Months", "24+ Months")))) -> 24+ Months | N113: =IF(E113<6,"12-18 Months", IF(E113<13, "18-24 Months", "24+ Months")) -> 24+ Months | O113: Other | P113: =IF(I113>=2, C113, IF(J113>=0.75, C113, 0)) -> 1 | Q113: =IF(I113>=2, C113, IF(AND(J113>=0.75, D113>=550), C113, 0)) -> 1 | R113: =IF(J113>=0.75, C113, 0) -> 1
A114: 110771 | B114: Albany County Sheriff's Office - NY | C114: 406 | D114: 140 | E114: 31 | F114: 0 | G114: 0 | H114: 0 | I114: 0 | J114: 0 | K114: 0 | L114: 46 | M114: =IF(E114<6,"0-6 Months", IF(E114<13, "6-12 Months", IF(E114<19, "12-24 Months", IF(E114<25, "12-24 Months", "24+ Months")))) -> 24+ Months | N114: =IF(E114<6,"12-18 Months", IF(E114<13, "18-24 Months", "24+ Months")) -> 24+ Months | O114: T1200 | P114: =IF(I114>=2, C114, IF(J114>=0.75, C114, 0)) -> 0 | Q114: =IF(I114>=2, C114, IF(AND(J114>=0.75, D114>=550), C114, 0)) -> 0 | R114: =IF(J114>=0.75, C114, 0) -> 0
A115: 106616 | B115: Elk Grove Village Police Dept. - IL | C115: 4 | D115: 92 | E115: 30 | F115: 25 | G115: 1 | H115: 1 | I115: 0.27 | J115: 0.01 | K115: 0.01 | L115: 40 | M115: =IF(E115<6,"0-6 Months", IF(E115<13, "6-12 Months", IF(E115<19, "12-24 Months", IF(E115<25, "12-24 Months", "24+ Months")))) -> 24+ Months | N115: =IF(E115<6,"12-18 Months", IF(E115<13, "18-24 Months", "24+ Months")) -> 24+ Months | O115: Other | P115: =IF(I115>=2, C115, IF(J115>=0.75, C115, 0)) -> 0 | Q115: =IF(I115>=2, C115, IF(AND(J115>=0.75, D115>=550), C115, 0)) -> 0 | R115: =IF(J115>=0.75, C115, 0) -> 0
A116: 293426 | B116: Tonkawa Police Dept. | C116: 8 | D116: 16 | E116: 30 | F116: 34 | G116: 25 | H116: 0 | I116: 2.13 | J116: 1.56 | K116: 0 | L116: 34 | M116: =IF(E116<6,"0-6 Months", IF(E116<13, "6-12 Months", IF(E116<19, "12-24 Months", IF(E116<25, "12-24 Months", "24+ Months")))) -> 24+ Months | N116: =IF(E116<6,"12-18 Months", IF(E116<13, "18-24 Months", "24+ Months")) -> 24+ Months | O116: Other | P116: =IF(I116>=2, C116, IF(J116>=0.75, C116, 0)) -> 8 | Q116: =IF(I116>=2, C116, IF(AND(J116>=0.75, D116>=550), C116, 0)) -> 8 | R116: =IF(J116>=0.75, C116, 0) -> 8
A117: 117408 | B117: Addison Police Department - IL | C117: 25 | D117: 66 | E117: 30 | F117: 103 | G117: 69 | H117: 0 | I117: 1.58 | J117: 1.06 | K117: 0 | L117: 10 | M117: =IF(E117<6,"0-6 Months", IF(E117<13, "6-12 Months", IF(E117<19, "12-24 Months", IF(E117<25, "12-24 Months", "24+ Months")))) -> 24+ Months | N117: =IF(E117<6,"12-18 Months", IF(E117<13, "18-24 Months", "24+ Months")) -> 24+ Months | O117: Other | P117: =IF(I117>=2, C117, IF(J117>=0.75, C117, 0)) -> 25 | Q117: =IF(I117>=2, C117, IF(AND(J117>=0.75, D117>=550), C117, 0)) -> 0 | R117: =IF(J117>=0.75, C117, 0) -> 25
A118: 198139 | B118: Black Mountain Police Dept. - NC | C118: 25 | D118: 16 | E118: 29 | F118: 12 | G118: 12 | H118: 12 | I118: 0.75 | J118: 0.75 | K118: 0.75 | L118: 4 | M118: =IF(E118<6,"0-6 Months", IF(E118<13, "6-12 Months", IF(E118<19, "12-24 Months", IF(E118<25, "12-24 Months", "24+ Months")))) -> 24+ Months | N118: =IF(E118<6,"12-18 Months", IF(E118<13, "18-24 Months", "24+ Months")) -> 24+ Months | O118: Other | P118: =IF(I118>=2, C118, IF(J118>=0.75, C118, 0)) -> 25 | Q118: =IF(I118>=2, C118, IF(AND(J118>=0.75, D118>=550), C118, 0)) -> 0 | R118: =IF(J118>=0.75, C118, 0) -> 25
A119: 470672 | B119: Harris County Constable Pct. 8 - TX | C119: 73 | D119: 73 | E119: 28 | F119: 156 | G119: 87 | H119: 87 | I119: 2.14 | J119: 1.19 | K119: 1.19 | L119: 0 | M119: =IF(E119<6,"0-6 Months", IF(E119<13, "6-12 Months", IF(E119<19, "12-24 Months", IF(E119<25, "12-24 Months", "24+ Months")))) -> 24+ Months | N119: =IF(E119<6,"12-18 Months", IF(E119<13, "18-24 Months", "24+ Months")) -> 24+ Months | O119: Other | P119: =IF(I119>=2, C119, IF(J119>=0.75, C119, 0)) -> 73 | Q119: =IF(I119>=2, C119, IF(AND(J119>=0.75, D119>=550), C119, 0)) -> 73 | R119: =IF(J119>=0.75, C119, 0) -> 73
A120: 110673 | B120: Do√±a Ana County Sheriff's Dept. - NM | C120: 190 | D120: 150 | E120: 28 | F120: 7 | G120: 9 | H120: 9 | I120: 0.05 | J120: 0.06 | K120: 0.06 | L120: 5 | M120: =IF(E120<6,"0-6 Months", IF(E120<13, "6-12 Months", IF(E120<19, "12-24 Months", IF(E120<25, "12-24 Months", "24+ Months")))) -> 24+ Months | N120: =IF(E120<6,"12-18 Months", IF(E120<13, "18-24 Months", "24+ Months")) -> 24+ Months | O120: T1200 | P120: =IF(I120>=2, C120, IF(J120>=0.75, C120, 0)) -> 0 | Q120: =IF(I120>=2, C120, IF(AND(J120>=0.75, D120>=550), C120, 0)) -> 0 | R120: =IF(J120>=0.75, C120, 0) -> 0
A121: 316716 | B121: BUFFALO CITY POLICE DEPT. - NY | C121: 724 | D121: 580 | E121: 28 | F121: 229 | G121: 174 | H121: 57 | I121: 0.39 | J121: 0.3 | K121: 0.1 | L121: 1048 | M121: =IF(E121<6,"0-6 Months", IF(E121<13, "6-12 Months", IF(E121<19, "12-24 Months", IF(E121<25, "12-24 Months", "24+ Months")))) -> 24+ Months | N121: =IF(E121<6,"12-18 Months", IF(E121<13, "18-24 Months", "24+ Months")) -> 24+ Months | O121: Major | P121: =IF(I121>=2, C121, IF(J121>=0.75, C121, 0)) -> 0 | Q121: =IF(I121>=2, C121, IF(AND(J121>=0.75, D121>=550), C121, 0)) -> 0 | R121: =IF(J121>=0.75, C121, 0) -> 0
A122: 108015 | B122: Birmingham Police Dept. - AL | C122: 775 | D122: 768 | E122: 28 | F122: 3 | G122: 3 | H122: 0 | I122: 0 | J122: 0 | K122: 0 | L122: 210 | M122: =IF(E122<6,"0-6 Months", IF(E122<13, "6-12 Months", IF(E122<19, "12-24 Months", IF(E122<25, "12-24 Months", "24+ Months")))) -> 24+ Months | N122: =IF(E122<6,"12-18 Months", IF(E122<13, "18-24 Months", "24+ Months")) -> 24+ Months | O122: Major | P122: =IF(I122>=2, C122, IF(J122>=0.75, C122, 0)) -> 0 | Q122: =IF(I122>=2, C122, IF(AND(J122>=0.75, D122>=550), C122, 0)) -> 0 | R122: =IF(J122>=0.75, C122, 0) -> 0
A123: 135122 | B123: Anne Arundel County Police Dept. - MD | C123: 862 | D123: 800 | E123: 28 | F123: 39 | G123: 5 | H123: 1 | I123: 0.05 | J123: 0.01 | K123: 0 | L123: 923 | M123: =IF(E123<6,"0-6 Months", IF(E123<13, "6-12 Months", IF(E123<19, "12-24 Months", IF(E123<25, "12-24 Months", "24+ Months")))) -> 24+ Months | N123: =IF(E123<6,"12-18 Months", IF(E123<13, "18-24 Months", "24+ Months")) -> 24+ Months | O123: Major | P123: =IF(I123>=2, C123, IF(J123>=0.75, C123, 0)) -> 0 | Q123: =IF(I123>=2, C123, IF(AND(J123>=0.75, D123>=550), C123, 0)) -> 0 | R123: =IF(J123>=0.75, C123, 0) -> 0
A124: 124496 | B124: Pittsburgh Bureau of Police - PA | C124: 992 | D124: 900 | E124: 28 | F124: 2105 | G124: 147 | H124: 14 | I124: 2.34 | J124: 0.16 | K124: 0.02 | L124: 858 | M124: =IF(E124<6,"0-6 Months", IF(E124<13, "6-12 Months", IF(E124<19, "12-24 Months", IF(E124<25, "12-24 Months", "24+ Months")))) -> 24+ Months | N124: =IF(E124<6,"12-18 Months", IF(E124<13, "18-24 Months", "24+ Months")) -> 24+ Months | O124: Major | P124: =IF(I124>=2, C124, IF(J124>=0.75, C124, 0)) -> 992 | Q124: =IF(I124>=2, C124, IF(AND(J124>=0.75, D124>=550), C124, 0)) -> 992 | R124: =IF(J124>=0.75, C124, 0) -> 0
A125: 465304 | B125: York City School Police Dept - PA | C125: 18 | D125: 24 | E125: 27 | F125: 33 | G125: 26 | H125: 0 | I125: 1.38 | J125: 1.08 | K125: 0 | L125: 3 | M125: =IF(E125<6,"0-6 Months", IF(E125<13, "6-12 Months", IF(E125<19, "12-24 Months", IF(E125<25, "12-24 Months", "24+ Months")))) -> 24+ Months | N125: =IF(E125<6,"12-18 Months", IF(E125<13, "18-24 Months", "24+ Months")) -> 24+ Months | O125: Other | P125: =IF(I125>=2, C125, IF(J125>=0.75, C125, 0)) -> 18 | Q125: =IF(I125>=2, C125, IF(AND(J125>=0.75, D125>=550), C125, 0)) -> 0 | R125: =IF(J125>=0.75, C125, 0) -> 18
... A190: 216820 | B190: Grapevine Police Dept. - TX | C190: 100 | D190: 115 | E190: 21 | F190: 254 | G190: 220 | H190: 196 | I190: 2.21 | J190: 1.91 | K190: 1.7 | L190: 4 | M190: =IF(E190<6,"0-6 Months", IF(E190<13, "6-12 Months", IF(E190<19, "12-24 Months", IF(E190<25, "12-24 Months", "24+ Months")))) -> 12-24 Months | N190: =IF(E190<6,"12-18 Months", IF(E190<13, "18-24 Months", "24+ Months")) -> 24+ Months | O190: T1200 | P190: =IF(I190>=2, C190, IF(J190>=0.75, C190, 0)) -> 100 | Q190: =IF(I190>=2, C190, IF(AND(J190>=0.75, D190>=550), C190, 0)) -> 100 | R190: =IF(J190>=0.75, C190, 0) -> 100
A191: CA0115746 | B191: CPKC Railway Police Service | C191: 105 | D191: 42 | E191: 21 | F191: 181 | G191: 135 | H191: 82 | I191: 4.31 | J191: 3.21 | K191: 1.95 | L191: 0 | M191: =IF(E191<6,"0-6 Months", IF(E191<13, "6-12 Months", IF(E191<19, "12-24 Months", IF(E191<25, "12-24 Months", "24+ Months")))) -> 12-24 Months | N191: =IF(E191<6,"12-18 Months", IF(E191<13, "18-24 Months", "24+ Months")) -> 24+ Months | O191: Other | P191: =IF(I191>=2, C191, IF(J191>=0.75, C191, 0)) -> 105 | Q191: =IF(I191>=2, C191, IF(AND(J191>=0.75, D191>=550), C191, 0)) -> 105 | R191: =IF(J191>=0.75, C191, 0) -> 105
A192: 113399 | B192: Cheektowaga Police Dept - NY | C192: 125 | D192: 100 | E192: 21 | F192: 139 | G192: 139 | H192: 122 | I192: 1.39 | J192: 1.39 | K192: 1.22 | L192: 8 | M192: =IF(E192<6,"0-6 Months", IF(E192<13, "6-12 Months", IF(E192<19, "12-24 Months", IF(E192<25, "12-24 Months", "24+ Months")))) -> 12-24 Months | N192: =IF(E192<6,"12-18 Months", IF(E192<13, "18-24 Months", "24+ Months")) -> 24+ Months | O192: T1200 | P192: =IF(I192>=2, C192, IF(J192>=0.75, C192, 0)) -> 125 | Q192: =IF(I192>=2, C192, IF(AND(J192>=0.75, D192>=550), C192, 0)) -> 0 | R192: =IF(J192>=0.75, C192, 0) -> 125
A193: 105754 | B193: Corona Police Dept. - CA | C193: 228 | D193: 166 | E193: 21 | F193: 0 | G193: 0 | H193: 0 | I193: 0 | J193: 0 | K193: 0 | L193: 0 | M193: =IF(E193<6,"0-6 Months", IF(E193<13, "6-12 Months", IF(E193<19, "12-24 Months", IF(E193<25, "12-24 Months", "24+ Months")))) -> 12-24 Months | N193: =IF(E193<6,"12-18 Months", IF(E193<13, "18-24 Months", "24+ Months")) -> 24+ Months | O193: T1200 | P193: =IF(I193>=2, C193, IF(J193>=0.75, C193, 0)) -> 0 | Q193: =IF(I193>=2, C193, IF(AND(J193>=0.75, D193>=550), C193, 0)) -> 0 | R193: =IF(J193>=0.75, C193, 0) -> 0
A194: 511036 | B194: Will County Sheriff Office Enforcement - IL | C194: 231 | D194: 240 | E194: 21 | F194: 1056 | G194: 1037 | H194: 43 | I194: 4.4 | J194: 4.32 | K194: 0.18 | L194: 10 | M194: =IF(E194<6,"0-6 Months", IF(E194<13, "6-12 Months", IF(E194<19, "12-24 Months", IF(E194<25, "12-24 Months", "24+ Months")))) -> 12-24 Months | N194: =IF(E194<6,"12-18 Months", IF(E194<13, "18-24 Months", "24+ Months")) -> 24+ Months | O194: T1200 | P194: =IF(I194>=2, C194, IF(J194>=0.75, C194, 0)) -> 231 | Q194: =IF(I194>=2, C194, IF(AND(J194>=0.75, D194>=550), C194, 0)) -> 231 | R194: =IF(J194>=0.75, C194, 0) -> 231
A195: 113387 | B195: Modesto Police Dept. - CA | C195: 267 | D195: 255 | E195: 21 | F195: 2 | G195: 0 | H195: 0 | I195: 0.01 | J195: 0 | K195: 0 | L195: 9 | M195: =IF(E195<6,"0-6 Months", IF(E195<13, "6-12 Months", IF(E195<19, "12-24 Months", IF(E195<25, "12-24 Months", "24+ Months")))) -> 12-24 Months | N195: =IF(E195<6,"12-18 Months", IF(E195<13, "18-24 Months", "24+ Months")) -> 24+ Months | O195: T1200 | P195: =IF(I195>=2, C195, IF(J195>=0.75, C195, 0)) -> 0 | Q195: =IF(I195>=2, C195, IF(AND(J195>=0.75, D195>=550), C195, 0)) -> 0 | R195: =IF(J195>=0.75, C195, 0) -> 0
A196: 106297 | B196: Springfield Police Department - MO | C196: 296 | D196: 235 | E196: 21 | F196: 523 | G196: 26 | H196: 0 | I196: 2.23 | J196: 0.11 | K196: 0 | L196: 136 | M196: =IF(E196<6,"0-6 Months", IF(E196<13, "6-12 Months", IF(E196<19, "12-24 Months", IF(E196<25, "12-24 Months", "24+ Months")))) -> 12-24 Months | N196: =IF(E196<6,"12-18 Months", IF(E196<13, "18-24 Months", "24+ Months")) -> 24+ Months | O196: T1200 | P196: =IF(I196>=2, C196, IF(J196>=0.75, C196, 0)) -> 296 | Q196: =IF(I196>=2, C196, IF(AND(J196>=0.75, D196>=550), C196, 0)) -> 296 | R196: =IF(J196>=0.75, C196, 0) -> 0
A197: 141269 | B197: Grand Rapids Police Dept. - MI | C197: 314 | D197: 300 | E197: 21 | F197: 962 | G197: 24 | H197: 15 | I197: 3.21 | J197: 0.08 | K197: 0.05 | L197: 3 | M197: =IF(E197<6,"0-6 Months", IF(E197<13, "6-12 Months", IF(E197<19, "12-24 Months", IF(E197<25, "12-24 Months", "24+ Months")))) -> 12-24 Months | N197: =IF(E197<6,"12-18 Months", IF(E197<13, "18-24 Months", "24+ Months")) -> 24+ Months | O197: T1200 | P197: =IF(I197>=2, C197, IF(J197>=0.75, C197, 0)) -> 314 | Q197: =IF(I197>=2, C197, IF(AND(J197>=0.75, D197>=550), C197, 0)) -> 314 | R197: =IF(J197>=0.75, C197, 0) -> 0
A198: 115314 | B198: Jefferson County Sheriff's Office - AL | C198: 487 | D198: 450 | E198: 21 | F198: 802 | G198: 347 | H198: 305 | I198: 1.78 | J198: 0.77 | K198: 0.68 | L198: 0 | M198: =IF(E198<6,"0-6 Months", IF(E198<13, "6-12 Months", IF(E198<19, "12-24 Months", IF(E198<25, "12-24 Months", "24+ Months")))) -> 12-24 Months | N198: =IF(E198<6,"12-18 Months", IF(E198<13, "18-24 Months", "24+ Months")) -> 24+ Months | O198: T1200 | P198: =IF(I198>=2, C198, IF(J198>=0.75, C198, 0)) -> 487 | Q198: =IF(I198>=2, C198, IF(AND(J198>=0.75, D198>=550), C198, 0)) -> 0 | R198: =IF(J198>=0.75, C198, 0) -> 487
A199: 112474 | B199: Pinellas County Sheriff's Office - FL | C199: 950 | D199: 1110 | E199: 21 | F199: 1647 | G199: 1048 | H199: 529 | I199: 1.48 | J199: 0.94 | K199: 0.48 | L199: 1331 | M199: =IF(E199<6,"0-6 Months", IF(E199<13, "6-12 Months", IF(E199<19, "12-24 Months", IF(E199<25, "12-24 Months", "24+ Months")))) -> 12-24 Months | N199: =IF(E199<6,"12-18 Months", IF(E199<13, "18-24 Months", "24+ Months")) -> 24+ Months | O199: Major | P199: =IF(I199>=2, C199, IF(J199>=0.75, C199, 0)) -> 950 | Q199: =IF(I199>=2, C199, IF(AND(J199>=0.75, D199>=550), C199, 0)) -> 950 | R199: =IF(J199>=0.75, C199, 0) -> 950
A200: 305270 | B200: Tilden Twp Police Dept. - PA | C200: 4 | D200: 4 | E200: 20 | F200: 0 | G200: 0 | H200: 0 | I200: 0 | J200: 0 | K200: 0 | L200: 0 | M200: =IF(E200<6,"0-6 Months", IF(E200<13, "6-12 Months", IF(E200<19, "12-24 Months", IF(E200<25, "12-24 Months", "24+ Months")))) -> 12-24 Months | N200: =IF(E200<6,"12-18 Months", IF(E200<13, "18-24 Months", "24+ Months")) -> 24+ Months | O200: Other | P200: =IF(I200>=2, C200, IF(J200>=0.75, C200, 0)) -> 0 | Q200: =IF(I200>=2, C200, IF(AND(J200>=0.75, D200>=550), C200, 0)) -> 0 | R200: =IF(J200>=0.75, C200, 0) -> 0
A201: 153711 | B201: Justin Police Dept. - TX | C201: 15 | D201: 16 | E201: 20 | F201: 1 | G201: 0 | H201: 0 | I201: 0.06 | J201: 0 | K201: 0 | L201: 0 | M201: =IF(E201<6,"0-6 Months", IF(E201<13, "6-12 Months", IF(E201<19, "12-24 Months", IF(E201<25, "12-24 Months", "24+ Months")))) -> 12-24 Months | N201: =IF(E201<6,"12-18 Months", IF(E201<13, "18-24 Months", "24+ Months")) -> 24+ Months | O201: Other | P201: =IF(I201>=2, C201, IF(J201>=0.75, C201, 0)) -> 0 | Q201: =IF(I201>=2, C201, IF(AND(J201>=0.75, D201>=550), C201, 0)) -> 0 | R201: =IF(J201>=0.75, C201, 0) -> 0
A202: 543347 | B202: CSX Railroad Police - FL | C202: 28 | D202: 104 | E202: 20 | F202: 80 | G202: 38 | H202: 0 | I202: 0.77 | J202: 0.37 | K202: 0 | L202: 0 | M202: =IF(E202<6,"0-6 Months", IF(E202<13, "6-12 Months", IF(E202<19, "12-24 Months", IF(E202<25, "12-24 Months", "24+ Months")))) -> 12-24 Months | N202: =IF(E202<6,"12-18 Months", IF(E202<13, "18-24 Months", "24+ Months")) -> 24+ Months | O202: T1200 | P202: =IF(I202>=2, C202, IF(J202>=0.75, C202, 0)) -> 0 | Q202: =IF(I202>=2, C202, IF(AND(J202>=0.75, D202>=550), C202, 0)) -> 0 | R202: =IF(J202>=0.75, C202, 0) -> 0
...

Sheet v2 Data
A1: AgencySlug | B1: AgencyName | C1: AgencySize | D1: VR_Licenses | E1: Eligibility_Cohort | F1: T12_SIM_Completions | G1: T6_SIM_Completions | H1: T3_SIM_Completions | I1: T12_SIM_Per_Person | J1: T6_SIM_Per_Person | K1: T3_SIM_Per_Person | L1: T6_Non_SIM_Completions | M1: 2025 Cohort | N1: 2026 Cohort | O1: Line Size | P1: No Qualifier Adopting Points | Q1: Majors Qualifier Adopting Points | R1: T6 0.75x Only
A2: 100239 | B2: Culver City Police Department - CA | C2: 100 | D2: 100 | E2: 11 | F2: 133 | G2: 0 | H2: 0 | I2: 1.33 | J2: 0 | K2: 0 | L2: 0 | M2: 6-12 Months | N2: 18-24 Months | O2: T1200 | P2: =IF(I2>=2, C2, IF(J2>=0.75, C2, 0)) -> 0 | Q2: =IF(I2>=2, C2, IF(AND(J2>=0.75, D2>=550), C2, 0)) -> 0 | R2: =IF(J2>=0.75, C2, 0) -> 0 | S2: =IF(A2=A3,TRUE,FALSE) -> FALSE
A3: 105331 | B3: Glendale Police Dept. - AZ | C3: 480 | D3: 487 | E3: 40 | F3: 6 | G3: 0 | H3: 0 | I3: 0.01 | J3: 0 | K3: 0 | L3: 0 | M3: 24+ Months | N3: 24+ Months | O3: T1200 | P3: =IF(I3>=2, C3, IF(J3>=0.75, C3, 0)) -> 0 | Q3: =IF(I3>=2, C3, IF(AND(J3>=0.75, D3>=550), C3, 0)) -> 0 | R3: =IF(J3>=0.75, C3, 0) -> 0 | S3: =IF(A3=A4,TRUE,FALSE) -> FALSE
A4: 105389 | B4: Bensalem Township Police Dept. - PA | C4: 111 | D4: 92 | E4: 48 | F4: 14 | G4: 8 | H4: 6 | I4: 0.15 | J4: 0.09 | K4: 0.07 | L4: 5 | M4: 24+ Months | N4: 24+ Months | O4: Other | P4: =IF(I4>=2, C4, IF(J4>=0.75, C4, 0)) -> 0 | Q4: =IF(I4>=2, C4, IF(AND(J4>=0.75, D4>=550), C4, 0)) -> 0 | R4: =IF(J4>=0.75, C4, 0) -> 0 | S4: =IF(A4=A5,TRUE,FALSE) -> FALSE
A5: 105459 | B5: Gering Police Department - NE | C5: 23 | D5: 21 | E5: 0 | F5: 0 | G5: 0 | H5: 0 | I5: 0 | J5: 0 | K5: 0 | L5: 0 | M5: 0-6 Months | N5: 12-18 Months | O5: Other | P5: =IF(I5>=2, C5, IF(J5>=0.75, C5, 0)) -> 0 | Q5: =IF(I5>=2, C5, IF(AND(J5>=0.75, D5>=550), C5, 0)) -> 0 | R5: =IF(J5>=0.75, C5, 0) -> 0 | S5: =IF(A5=A6,TRUE,FALSE) -> FALSE
A6: 105469 | B6: San Bernardino County Sheriff's Dept. - CA | C6: 950 | D6: 1000 | E6: 10 | F6: 5114 | G6: 664 | H6: 211 | I6: 5.11 | J6: 0.66 | K6: 0.21 | L6: 20 | M6: 6-12 Months | N6: 18-24 Months | O6: Major | P6: =IF(I6>=2, C6, IF(J6>=0.75, C6, 0)) -> 950 | Q6: =IF(I6>=2, C6, IF(AND(J6>=0.75, D6>=550), C6, 0)) -> 950 | R6: =IF(J6>=0.75, C6, 0) -> 0 | S6: =IF(A6=A7,TRUE,FALSE) -> FALSE
A7: 105506 | B7: Chandler Police Dept. - AZ | C7: 394 | D7: 364 | E7: 13 | F7: 201 | G7: 116 | H7: 52 | I7: 0.55 | J7: 0.32 | K7: 0.14 | L7: 38 | M7: 12-24 Months | N7: 24+ Months | O7: T1200 | P7: =IF(I7>=2, C7, IF(J7>=0.75, C7, 0)) -> 0 | Q7: =IF(I7>=2, C7, IF(AND(J7>=0.75, D7>=550), C7, 0)) -> 0 | R7: =IF(J7>=0.75, C7, 0) -> 0 | S7: =IF(A7=A8,TRUE,FALSE) -> FALSE
A8: 105516 | B8: Mesa Police Department | C8: 1079 | D8: 720 | E8: 16 | F8: 762 | G8: 623 | H8: 538 | I8: 1.06 | J8: 0.87 | K8: 0.75 | L8: 8 | M8: 12-24 Months | N8: 24+ Months | O8: Major | P8: =IF(I8>=2, C8, IF(J8>=0.75, C8, 0)) -> 1079 | Q8: =IF(I8>=2, C8, IF(AND(J8>=0.75, D8>=550), C8, 0)) -> 1079 | R8: =IF(J8>=0.75, C8, 0) -> 1079 | S8: =IF(A8=A9,TRUE,FALSE) -> FALSE
A9: 105678 | B9: East Point Police Dept. - GA | C9: 90 | D9: 115 | E9: 42 | F9: 265 | G9: 63 | H9: 58 | I9: 2.3 | J9: 0.55 | K9: 0.5 | L9: 256 | M9: 24+ Months | N9: 24+ Months | O9: T1200 | P9: =IF(I9>=2, C9, IF(J9>=0.75, C9, 0)) -> 90 | Q9: =IF(I9>=2, C9, IF(AND(J9>=0.75, D9>=550), C9, 0)) -> 90 | R9: =IF(J9>=0.75, C9, 0) -> 0 | S9: =IF(A9=A10,TRUE,FALSE) -> FALSE
A10: 105690 | B10: Laurens County Sheriff's Office - SC | C10: 140 | D10: 100 | E10: 0 | F10: 3 | G10: 3 | H10: 3 | I10: 0.03 | J10: 0.03 | K10: 0.03 | L10: 0 | M10: 0-6 Months | N10: 12-18 Months | O10: T1200 | P10: =IF(I10>=2, C10, IF(J10>=0.75, C10, 0)) -> 0 | Q10: =IF(I10>=2, C10, IF(AND(J10>=0.75, D10>=550), C10, 0)) -> 0 | R10: =IF(J10>=0.75, C10, 0) -> 0 | S10: =IF(A10=A11,TRUE,FALSE) -> FALSE
A11: 105702 | B11: Tampa Police Department - FL | C11: 928 | D11: 1000 | E11: 11 | F11: 1795 | G11: 1068 | H11: 99 | I11: 1.8 | J11: 1.07 | K11: 0.1 | L11: 63 | M11: 6-12 Months | N11: 18-24 Months | O11: Major | P11: =IF(I11>=2, C11, IF(J11>=0.75, C11, 0)) -> 928 | Q11: =IF(I11>=2, C11, IF(AND(J11>=0.75, D11>=550), C11, 0)) -> 928 | R11: =IF(J11>=0.75, C11, 0) -> 928 | S11: =IF(A11=A12,TRUE,FALSE) -> FALSE
A12: 105703 | B12: Yuma County Sheriff's Office - AZ | C12: 71 | D12: 100 | E12: 2 | F12: 0 | G12: 0 | H12: 0 | I12: 0 | J12: 0 | K12: 0 | L12: 0 | M12: 0-6 Months | N12: 12-18 Months | O12: T1200 | P12: =IF(I12>=2, C12, IF(J12>=0.75, C12, 0)) -> 0 | Q12: =IF(I12>=2, C12, IF(AND(J12>=0.75, D12>=550), C12, 0)) -> 0 | R12: =IF(J12>=0.75, C12, 0) -> 0 | S12: =IF(A12=A13,TRUE,FALSE) -> FALSE
A13: 105706 | B13: Aurora Police Dept. - CO | C13: 760 | D13: 778 | E13: 34 | F13: 66 | G13: 26 | H13: 20 | I13: 0.08 | J13: 0.03 | K13: 0.03 | L13: 807 | M13: 24+ Months | N13: 24+ Months | O13: Major | P13: =IF(I13>=2, C13, IF(J13>=0.75, C13, 0)) -> 0 | Q13: =IF(I13>=2, C13, IF(AND(J13>=0.75, D13>=550), C13, 0)) -> 0 | R13: =IF(J13>=0.75, C13, 0) -> 0 | S13: =IF(A13=A14,TRUE,FALSE) -> FALSE
... A1266: 611350 | B1266: Starr County Constable Pct 4. | C1266: 0 | D1266: 1 | E1266: 0 | F1266: 0 | G1266: 0 | H1266: 0 | I1266: 0 | J1266: 0 | K1266: 0 | L1266: 0 | M1266: 0-6 Months | N1266: 12-18 Months | O1266: Other | P1266: =IF(I1266>=2, C1266, IF(J1266>=0.75, C1266, 0)) -> 0 | Q1266: =IF(I1266>=2, C1266, IF(AND(J1266>=0.75, D1266>=550), C1266, 0)) -> 0 | R1266: =IF(J1266>=0.75, C1266, 0) -> 0 | S1266: =IF(A1266=A1267,TRUE,FALSE) -> FALSE
A1267: AU0115817 | B1267: Office of Sheriff of New South Wales | C1267: 5 | D1267: 5 | E1267: 5 | F1267: 3 | G1267: 3 | H1267: 0 | I1267: 0.6 | J1267: 0.6 | K1267: 0 | L1267: 85 | M1267: 0-6 Months | N1267: 12-18 Months | O1267: Other | P1267: =IF(I1267>=2, C1267, IF(J1267>=0.75, C1267, 0)) -> 0 | Q1267: =IF(I1267>=2, C1267, IF(AND(J1267>=0.75, D1267>=550), C1267, 0)) -> 0 | R1267: =IF(J1267>=0.75, C1267, 0) -> 0 | S1267: =IF(A1267=A1268,TRUE,FALSE) -> FALSE
A1268: CA0115409 | B1268: Peel Regional Police Service - CAN | C1268: 2119 | D1268: 750 | E1268: 7 | F1268: 366 | G1268: 366 | H1268: 208 | I1268: 0.49 | J1268: 0.49 | K1268: 0.28 | L1268: 1969 | M1268: 6-12 Months | N1268: 18-24 Months | O1268: Major | P1268: =IF(I1268>=2, C1268, IF(J1268>=0.75, C1268, 0)) -> 0 | Q1268: =IF(I1268>=2, C1268, IF(AND(J1268>=0.75, D1268>=550), C1268, 0)) -> 0 | R1268: =IF(J1268>=0.75, C1268, 0) -> 0 | S1268: =IF(A1268=A1269,TRUE,FALSE) -> FALSE
A1269: CA0115465 | B1269: Barrie Police Service | C1269: 322 | D1269: 155 | E1269: 17 | F1269: 742 | G1269: 52 | H1269: 30 | I1269: 4.79 | J1269: 0.34 | K1269: 0.19 | L1269: 125 | M1269: 12-24 Months | N1269: 24+ Months | O1269: T1200 | P1269: =IF(I1269>=2, C1269, IF(J1269>=0.75, C1269, 0)) -> 322 | Q1269: =IF(I1269>=2, C1269, IF(AND(J1269>=0.75, D1269>=550), C1269, 0)) -> 322 | R1269: =IF(J1269>=0.75, C1269, 0) -> 0 | S1269: =IF(A1269=A1270,TRUE,FALSE) -> FALSE
